Workbook

Sheet 0_Huong_dan
A1: SỔ TÍNH TOÁN ĐẦY ĐỦ – TOÀN BỘ SỐ LIỆU CỦA BÀI BÁO "KHOẢNG CÁCH TMĐT GIỮA 63 TỈNH, 2017–2024"
A3: Đây là bản "làm thật": mọi con số trong bài đều truy được về sheet 1_Du_lieu qua công thức, trừ các thống kê Excel không có hàm (đánh dấu màu cam).
A4: MÀU Ô: VÀNG = số liệu gốc nhập vào (VECOM, Niên giám); XANH LÁ = công thức Excel (bấm vào ô để xem); XÁM = kết quả cuối được dẫn trong bài; CAM = giá trị dán từ script 01_phan_tich.py (Excel không có hàm: sai số chuẩn cụm theo tỉnh, p-value vững HC1, VIF, kiểm định Wald, hiệu ứng cố định tỉnh, Oaxaca–Blinder bootstrap).
A5: Sheet cuối "11_Doi_chieu" so sánh từng con số Excel tính được với Python: cột "Chênh lệch" phải ≈ 0.
A6: Số trong Excel dùng dấu chấm thập phân (định dạng máy); bài báo in dấu phẩy. Các số trong bài đã làm tròn 3–4 chữ số.
A7: Hàng dữ liệu được sắp theo NĂM rồi TỈNH (63 tỉnh mỗi năm, cùng thứ tự) nên "năm trước" của một dòng luôn nằm đúng 63 dòng phía trên – các biến trễ (_L1) dựa vào quy tắc đó.
A9: Sheet | B9: Nội dung | C9: Tương ứng trong bài báo | D9: Loại tính toán
A10: 1_Du_lieu | B10: 504 dòng tỉnh–năm: EBI + 4 trụ cột (VECOM), biến Niên giám, biến dẫn xuất ln(…), biến trễ 1 năm | C10: Bảng 1 (mô tả biến), Mục 3.1–3.2 | D10: Nhập + công thức dẫn xuất
A11: 2_Bang1_Mo_ta | B11: Thống kê mô tả 16 biến | C11: Bảng 1 | D11: Công thức
A12: 3_Bang2_EBI_tuong_doi | B12: EBI tương đối từng tỉnh–năm; trung bình vùng theo giai đoạn; ma trận vùng × năm; biểu đồ | C12: Bảng 2, Hình 2, Mục 3.1, 4.1 | D12: Công thức + biểu đồ
A13: 4_Bang3_Gini_Theil | B13: Gini, CV, SD ln, Theil-T, MLD và phân rã giữa/trong 6 vùng từng năm; kiểm tra bỏ HN & TP.HCM; biểu đồ | C13: Bảng 3, Hình 3, Hình 4, phương trình (1) | D13: Công thức + biểu đồ
A14: 5_Bang4_Gini_tru_cot | B14: Phân rã Gini theo trụ cột S·G·R từng năm | C14: Bảng 4, Mục 4.2 | D14: Công thức
A15: 6_Bang5a_Sigma | B15: Hệ số biến thiên EBI và 3 trụ cột theo năm; biểu đồ | C15: Hình 5, Mục 4.3 | D15: Công thức + biểu đồ
A16: 7_Bang5_Beta | B16: Hội tụ beta tuyệt đối và có điều kiện 3 cửa sổ; λ, bán hội tụ; biểu đồ điểm + đường xu hướng | C16: Bảng 5, 5b, Hình 6, 7, phương trình (2) | D16: Công thức (LINEST) + dán SE vững, bảng động
A17: 8_Bang6_7_9_OLS | B17: Hồi quy OLS gộp M1–M4, hệ số chuẩn hóa, ma trận tương quan, biến giả vùng M5–M6, cắt ngang 2024 | C17: Bảng 6, 7, 9, phương trình (3) | D17: Công thức (LINEST) + dán SE cụm, p, VIF, Wald, FE tỉnh
A18: 9_Bang8_Oaxaca | B18: Phân tách Oaxaca–Blinder lõi – ngoại vi: trung bình nhóm, phần nguồn lực theo biến, tổng; biểu đồ | C18: Bảng 8, 8b, Hình 8, phương trình (4) | D18: Công thức (trung bình, tích) + dán β*, bootstrap
A19: 10_So_lieu_khac | B19: Top/bottom 5 tỉnh 2024, tỷ số max/trung vị, P90/P10, lõi – ngoại vi theo năm, tỉnh thiếu số liệu | C19: Mục 3.1, 4.1, 4.3 | D19: Công thức
A20: 11_Doi_chieu | B20: Đối chiếu Excel ↔ Python cho mọi con số then chốt | C20: — | D20: Kiểm tra

Sheet 1_Du_lieu
A1: DỮ LIỆU GỐC 63 TỈNH × 8 NĂM (sắp theo năm, rồi tỉnh)
A2: Cột vàng: nhập từ VECOM (EBI, trụ cột) và Niên giám Thống kê. Cột xanh: dẫn xuất bằng công thức. Ô EBI trống = VECOM không xếp hạng tỉnh đó năm đó.
A4: Tỉnh | B4: Năm | C4: Vùng (6 vùng NGTK) | D4: Lõi=1 (ĐNB, ĐBSH) | E4: EBI | F4: NNL&HT | G4: B2C | H4: B2B | I4: G2B (≤2020) | J4: Dân số (nghìn người) | K4: GRDP/người (tr.đ) | L4: DN/1.000 dân | M4: % thành thị | N4: % LĐ qua đào tạo | O4: % hộ có máy tính | P4: Hàng hóa đường bộ (nghìn tấn) | Q4: Hàng hóa/người (tấn) | R4: Siêu thị | S4: TTTM | T4: ST+TTTM/100.000 dân | U4: FDI lũy kế/người (USD) | V4: ln(EBI) | W4: ln(GRDP/người) | X4: ln(hàng hóa/người) | Y4: ln(1+FDI/người) | Z4: ln(GRDP/người) (t−1) | AA4: Mật độ DN (DN/1.000 dân) (t−1) | AB4: Tỷ lệ dân số thành thị (%) (t−1) | AC4: Tỷ lệ LĐ qua đào tạo (%) (t−1) | AD4: Tỷ lệ hộ có máy tính (%) (t−1) | AE4: ln(Hàng hóa vận chuyển đường bộ/người) (t−1) | AF4: Siêu thị + TTTM/100.000 dân (t−1) | AG4: ln(1 + FDI lũy kế/người) (t−1)
A5: An Giang | B5: 2017 | C5: ĐBSCL | D5: =IF(OR(C5="ĐNB",C5="ĐBSH"),1,0) -> 0 | E5: 27.2 | F5: 12.4 | G5: 40.4 | H5: 14.5 | I5: 70.5 | J5: 1954.2 | L5: 2.259 | M5: 30.99 | N5: 12.5 | P5: 5515.3 | Q5: =IF(P5="","",P5/J5) -> 2.8222802 | R5: 6 | S5: 2 | T5: =(R5+S5)/J5*100 -> 0.40937468 | U5: 101.4 | V5: =IF(E5="","",LN(E5)) -> 3.303217 | W5: =IF(K5="","",LN(K5)) | X5: =IF(Q5="","",LN(Q5)) -> 1.0375451 | Y5: =LN(1+U5) -> 4.6288867 | Z5: =IF(B5=2017,"",W-58) | AA5: =IF(B5=2017,"",L-58) | AB5: =IF(B5=2017,"",M-58) | AC5: =IF(B5=2017,"",N-58) | AD5: =IF(B5=2017,"",O-58) | AE5: =IF(B5=2017,"",X-58) | AF5: =IF(B5=2017,"",T-58) | AG5: =IF(B5=2017,"",Y-58)
A6: Bà Rịa - Vũng Tàu | B6: 2017 | C6: ĐNB | D6: =IF(OR(C6="ĐNB",C6="ĐBSH"),1,0) -> 1 | E6: 37.8 | F6: 21.3 | G6: 57 | H6: 28.6 | I6: 57 | J6: 1127.2 | L6: 7.945 | M6: 56.76 | N6: 26.5 | P6: 5908.1 | Q6: =IF(P6="","",P6/J6) -> 5.2413946 | R6: 8 | S6: 3 | T6: =(R6+S6)/J6*100 -> 0.97586941 | U6: 23809.5 | V6: =IF(E6="","",LN(E6)) -> 3.6323091 | W6: =IF(K6="","",LN(K6)) | X6: =IF(Q6="","",LN(Q6)) -> 1.6565876 | Y6: =LN(1+U6) -> 10.077882 | Z6: =IF(B6=2017,"",W-57) | AA6: =IF(B6=2017,"",L-57) | AB6: =IF(B6=2017,"",M-57) | AC6: =IF(B6=2017,"",N-57) | AD6: =IF(B6=2017,"",O-57) | AE6: =IF(B6=2017,"",X-57) | AF6: =IF(B6=2017,"",T-57) | AG6: =IF(B6=2017,"",Y-57)
A7: Bình Dương | B7: 2017 | C7: ĐNB | D7: =IF(OR(C7="ĐNB",C7="ĐBSH"),1,0) -> 1 | E7: 43 | F7: 21.2 | G7: 62.1 | H7: 36.7 | I7: 69.5 | J7: 2227.2 | L7: 10.316 | M7: 76.19 | N7: 18.7 | P7: 47046.7 | Q7: =IF(P7="","",P7/J7) -> 21.123698 | R7: 11 | S7: 3 | T7: =(R7+S7)/J7*100 -> 0.62859195 | U7: 13622 | V7: =IF(E7="","",LN(E7)) -> 3.7612001 | W7: =IF(K7="","",LN(K7)) | X7: =IF(Q7="","",LN(Q7)) -> 3.0503955 | Y7: =LN(1+U7) -> 9.5195148 | Z7: =IF(B7=2017,"",W-56) | AA7: =IF(B7=2017,"",L-56) | AB7: =IF(B7=2017,"",M-56) | AC7: =IF(B7=2017,"",N-56) | AD7: =IF(B7=2017,"",O-56) | AE7: =IF(B7=2017,"",X-56) | AF7: =IF(B7=2017,"",T-56) | AG7: =IF(B7=2017,"",Y-56)
A8: Bình Phước | B8: 2017 | C8: ĐNB | D8: =IF(OR(C8="ĐNB",C8="ĐBSH"),1,0) -> 1 | E8: 24 | F8: 11 | G8: 35 | H8: 17.8 | I8: 49 | J8: 972.6 | L8: 4.16 | M8: 22.27 | N8: 14 | P8: 2442.3 | Q8: =IF(P8="","",P8/J8) -> 2.5111043 | R8: 2 | S8: 3 | T8: =(R8+S8)/J8*100 -> 0.51408596 | U8: 2016 | V8: =IF(E8="","",LN(E8)) -> 3.1780538 | W8: =IF(K8="","",LN(K8)) | X8: =IF(Q8="","",LN(Q8)) -> 0.9207226 | Y8: =LN(1+U8) -> 7.6093665 | Z8: =IF(B8=2017,"",W-55) | AA8: =IF(B8=2017,"",L-55) | AB8: =IF(B8=2017,"",M-55) | AC8: =IF(B8=2017,"",N-55) | AD8: =IF(B8=2017,"",O-55) | AE8: =IF(B8=2017,"",X-55) | AF8: =IF(B8=2017,"",T-55) | AG8: =IF(B8=2017,"",Y-55)
A9: Bình Thuận | B9: 2017 | C9: BTB&DHMT | D9: =IF(OR(C9="ĐNB",C9="ĐBSH"),1,0) -> 0 | E9: 29.5 | F9: 14.5 | G9: 41.5 | H9: 21.9 | I9: 60.9 | J9: 1220.5 | L9: 3.426 | M9: 38.32 | N9: 15.6 | P9: 7273.4 | Q9: =IF(P9="","",P9/J9) -> 5.9593609 | R9: 2 | S9: 1 | T9: =(R9+S9)/J9*100 -> 0.2458009 | U9: 2922.4 | V9: =IF(E9="","",LN(E9)) -> 3.3843903 | W9: =IF(K9="","",LN(K9)) | X9: =IF(Q9="","",LN(Q9)) -> 1.7849632 | Y9: =LN(1+U9) -> 7.9805026 | Z9: =IF(B9=2017,"",W-54) | AA9: =IF(B9=2017,"",L-54) | AB9: =IF(B9=2017,"",M-54) | AC9: =IF(B9=2017,"",N-54) | AD9: =IF(B9=2017,"",O-54) | AE9: =IF(B9=2017,"",X-54) | AF9: =IF(B9=2017,"",T-54) | AG9: =IF(B9=2017,"",Y-54)
A10: Bình Định | B10: 2017 | C10: BTB&DHMT | D10: =IF(OR(C10="ĐNB",C10="ĐBSH"),1,0) -> 0 | E10: 29.9 | F10: 15.5 | G10: 41 | H10: 24.4 | I10: 56.5 | J10: 1487.7 | L10: 3.96 | M10: 31.87 | N10: 16.9 | P10: 17047.4 | Q10: =IF(P10="","",P10/J10) -> 11.458896 | R10: 7 | S10: 4 | T10: =(R10+S10)/J10*100 -> 0.73939638 | U10: 451.6 | V10: =IF(E10="","",LN(E10)) -> 3.3978585 | W10: =IF(K10="","",LN(K10)) | X10: =IF(Q10="","",LN(Q10)) -> 2.4387664 | Y10: =LN(1+U10) -> 6.1150087 | Z10: =IF(B10=2017,"",W-53) | AA10: =IF(B10=2017,"",L-53) | AB10: =IF(B10=2017,"",M-53) | AC10: =IF(B10=2017,"",N-53) | AD10: =IF(B10=2017,"",O-53) | AE10: =IF(B10=2017,"",X-53) | AF10: =IF(B10=2017,"",T-53) | AG10: =IF(B10=2017,"",Y-53)
A11: Bạc Liêu | B11: 2017 | C11: ĐBSCL | D11: =IF(OR(C11="ĐNB",C11="ĐBSH"),1,0) -> 0 | J11: 897.7 | L11: 1.768 | M11: 27.48 | N11: 11.3 | P11: 2017.4 | Q11: =IF(P11="","",P11/J11) -> 2.2472987 | R11: 5 | S11: 1 | T11: =(R11+S11)/J11*100 -> 0.66837474 | U11: 79.6 | V11: =IF(E11="","",LN(E11)) | W11: =IF(K11="","",LN(K11)) | X11: =IF(Q11="","",LN(Q11)) -> 0.8097289 | Y11: =LN(1+U11) -> 4.3894986 | Z11: =IF(B11=2017,"",W-52) | AA11: =IF(B11=2017,"",L-52) | AB11: =IF(B11=2017,"",M-52) | AC11: =IF(B11=2017,"",N-52) | AD11: =IF(B11=2017,"",O-52) | AE11: =IF(B11=2017,"",X-52) | AF11: =IF(B11=2017,"",T-52) | AG11: =IF(B11=2017,"",Y-52)
A12: Bắc Giang | B12: 2017 | C12: TDMNPB | D12: =IF(OR(C12="ĐNB",C12="ĐBSH"),1,0) -> 0 | E12: 30 | F12: 11.6 | G12: 40.5 | H12: 25 | I12: 69 | J12: 1736.8 | L12: 2.715 | M12: 11.41 | N12: 17.9 | P12: 16517 | Q12: =IF(P12="","",P12/J12) -> 9.5100184 | R12: 7 | S12: 8 | T12: =(R12+S12)/J12*100 -> 0.8636573 | U12: 2581.5 | V12: =IF(E12="","",LN(E12)) -> 3.4011974 | W12: =IF(K12="","",LN(K12)) | X12: =IF(Q12="","",LN(Q12)) -> 2.2523458 | Y12: =LN(1+U12) -> 7.8565132 | Z12: =IF(B12=2017,"",W-51) | AA12: =IF(B12=2017,"",L-51) | AB12: =IF(B12=2017,"",M-51) | AC12: =IF(B12=2017,"",N-51) | AD12: =IF(B12=2017,"",O-51) | AE12: =IF(B12=2017,"",X-51) | AF12: =IF(B12=2017,"",T-51) | AG12: =IF(B12=2017,"",Y-51)
A13: Bắc Kạn | B13: 2017 | C13: TDMNPB | D13: =IF(OR(C13="ĐNB",C13="ĐBSH"),1,0) -> 0 | E13: 22.6 | F13: 13.8 | G13: 26.8 | H13: 18.5 | I13: 48.6 | J13: 309.9 | L13: 2.13 | M13: 19.81 | N13: 17.2 | P13: 1630 | Q13: =IF(P13="","",P13/J13) -> 5.2597612 | R13: 1 | S13: 0 | T13: =(R13+S13)/J13*100 -> 0.32268474 | U13: 41.9 | V13: =IF(E13="","",LN(E13)) -> 3.1179499 | W13: =IF(K13="","",LN(K13)) | X13: =IF(Q13="","",LN(Q13)) -> 1.6600856 | Y13: =LN(1+U13) -> 3.7588718 | Z13: =IF(B13=2017,"",W-50) | AA13: =IF(B13=2017,"",L-50) | AB13: =IF(B13=2017,"",M-50) | AC13: =IF(B13=2017,"",N-50) | AD13: =IF(B13=2017,"",O-50) | AE13: =IF(B13=2017,"",X-50) | AF13: =IF(B13=2017,"",T-50) | AG13: =IF(B13=2017,"",Y-50)
A14: Bắc Ninh | B14: 2017 | C14: ĐBSH | D14: =IF(OR(C14="ĐNB",C14="ĐBSH"),1,0) -> 1 | E14: 38.9 | F14: 19.8 | G14: 57.8 | H14: 30.3 | I14: 65.1 | J14: 1297.8 | L14: 6.644 | M14: 27.38 | N14: 22.4 | P14: 19099.4 | Q14: =IF(P14="","",P14/J14) -> 14.716751 | R14: 23 | S14: 2 | T14: =(R14+S14)/J14*100 -> 1.9263369 | U14: 12466 | V14: =IF(E14="","",LN(E14)) -> 3.6609943 | W14: =IF(K14="","",LN(K14)) | X14: =IF(Q14="","",LN(Q14)) -> 2.6889864 | Y14: =LN(1+U14) -> 9.4308404 | Z14: =IF(B14=2017,"",W-49) | AA14: =IF(B14=2017,"",L-49) | AB14: =IF(B14=2017,"",M-49) | AC14: =IF(B14=2017,"",N-49) | AD14: =IF(B14=2017,"",O-49) | AE14: =IF(B14=2017,"",X-49) | AF14: =IF(B14=2017,"",T-49) | AG14: =IF(B14=2017,"",Y-49)
A15: Bến Tre | B15: 2017 | C15: ĐBSCL | D15: =IF(OR(C15="ĐNB",C15="ĐBSH"),1,0) -> 0 | E15: 28.1 | F15: 15.8 | G15: 36.5 | H15: 19.5 | I15: 66 | J15: 1282.4 | L15: 2.281 | M15: 9.84 | N15: 12.9 | P15: 2964.6 | Q15: =IF(P15="","",P15/J15) -> 2.3117592 | R15: 2 | S15: 1 | T15: =(R15+S15)/J15*100 -> 0.23393637 | U15: 674.8 | V15: =IF(E15="","",LN(E15)) -> 3.3357696 | W15: =IF(K15="","",LN(K15)) | X15: =IF(Q15="","",LN(Q15)) -> 0.83800879 | Y15: =LN(1+U15) -> 6.5158972 | Z15: =IF(B15=2017,"",W-48) | AA15: =IF(B15=2017,"",L-48) | AB15: =IF(B15=2017,"",M-48) | AC15: =IF(B15=2017,"",N-48) | AD15: =IF(B15=2017,"",O-48) | AE15: =IF(B15=2017,"",X-48) | AF15: =IF(B15=2017,"",T-48) | AG15: =IF(B15=2017,"",Y-48)
A16: Cao Bằng | B16: 2017 | C16: TDMNPB | D16: =IF(OR(C16="ĐNB",C16="ĐBSH"),1,0) -> 0 | J16: 526.4 | L16: 1.795 | M16: 21.94 | N16: 21 | P16: 2956.2 | Q16: =IF(P16="","",P16/J16) -> 5.6158815 | R16: 4 | S16: 0 | T16: =(R16+S16)/J16*100 -> 0.75987842 | U16: 151.8 | V16: =IF(E16="","",LN(E16)) | W16: =IF(K16="","",LN(K16)) | X16: =IF(Q16="","",LN(Q16)) -> 1.7255986 | Y16: =LN(1+U16) -> 5.0291299 | Z16: =IF(B16=2017,"",W-47) | AA16: =IF(B16=2017,"",L-47) | AB16: =IF(B16=2017,"",M-47) | AC16: =IF(B16=2017,"",N-47) | AD16: =IF(B16=2017,"",O-47) | AE16: =IF(B16=2017,"",X-47) | AF16: =IF(B16=2017,"",T-47) | AG16: =IF(B16=2017,"",Y-47)
A17: Cà Mau | B17: 2017 | C17: ĐBSCL | D17: =IF(OR(C17="ĐNB",C17="ĐBSH"),1,0) -> 0 | E17: 21.2 | F17: 11.1 | G17: 24 | H17: 18.6 | I17: 51 | J17: 1197 | L17: 2.84 | M17: 22.46 | N17: 10.4 | P17: 453.7 | Q17: =IF(P17="","",P17/J17) -> 0.37903091 | R17: 4 | S17: 3 | T17: =(R17+S17)/J17*100 -> 0.58479532 | U17: 33.7 | V17: =IF(E17="","",LN(E17)) -> 3.0540012 | W17: =IF(K17="","",LN(K17)) | X17: =IF(Q17="","",LN(Q17)) -> -0.97013752 | Y17: =LN(1+U17) -> 3.5467397 | Z17: =IF(B17=2017,"",W-46) | AA17: =IF(B17=2017,"",L-46) | AB17: =IF(B17=2017,"",M-46) | AC17: =IF(B17=2017,"",N-46) | AD17: =IF(B17=2017,"",O-46) | AE17: =IF(B17=2017,"",X-46) | AF17: =IF(B17=2017,"",T-46) | AG17: =IF(B17=2017,"",Y-46)
A18: Cần Thơ | B18: 2017 | C18: ĐBSCL | D18: =IF(OR(C18="ĐNB",C18="ĐBSH"),1,0) -> 0 | E18: 37.2 | F18: 17.3 | G18: 55.5 | H18: 26.2 | I18: 75 | J18: 1222.4 | L18: 6.107 | M18: 68.94 | N18: 21.1 | P18: 3659 | Q18: =IF(P18="","",P18/J18) -> 2.9932919 | R18: 12 | S18: 6 | T18: =(R18+S18)/J18*100 -> 1.4725131 | U18: 526.5 | V18: =IF(E18="","",LN(E18)) -> 3.6163088 | W18: =IF(K18="","",LN(K18)) | X18: =IF(Q18="","",LN(Q18)) -> 1.0963737 | Y18: =LN(1+U18) -> 6.2681489 | Z18: =IF(B18=2017,"",W-45) | AA18: =IF(B18=2017,"",L-45) | AB18: =IF(B18=2017,"",M-45) | AC18: =IF(B18=2017,"",N-45) | AD18: =IF(B18=2017,"",O-45) | AE18: =IF(B18=2017,"",X-45) | AF18: =IF(B18=2017,"",T-45) | AG18: =IF(B18=2017,"",Y-45)
A19: Gia Lai | B19: 2017 | C19: TN | D19: =IF(OR(C19="ĐNB",C19="ĐBSH"),1,0) -> 0 | E19: 23.7 | F19: 10 | G19: 33 | H19: 21 | I19: 45 | J19: 1468.9 | L19: 2.37 | M19: 28.89 | N19: 11 | P19: 16943 | Q19: =IF(P19="","",P19/J19) -> 11.534482 | R19: 17 | S19: 1 | T19: =(R19+S19)/J19*100 -> 1.2254068 | U19: 8.3 | V19: =IF(E19="","",LN(E19)) -> 3.165475 | W19: =IF(K19="","",LN(K19)) | X19: =IF(Q19="","",LN(Q19)) -> 2.4453409 | Y19: =LN(1+U19) -> 2.2300144 | Z19: =IF(B19=2017,"",W-44) | AA19: =IF(B19=2017,"",L-44) | AB19: =IF(B19=2017,"",M-44) | AC19: =IF(B19=2017,"",N-44) | AD19: =IF(B19=2017,"",O-44) | AE19: =IF(B19=2017,"",X-44) | AF19: =IF(B19=2017,"",T-44) | AG19: =IF(B19=2017,"",Y-44)
A20: Hà Giang | B20: 2017 | C20: TDMNPB | D20: =IF(OR(C20="ĐNB",C20="ĐBSH"),1,0) -> 0 | J20: 833.7 | L20: 1.363 | M20: 15.02 | N20: 12.5 | P20: 2129.2 | Q20: =IF(P20="","",P20/J20) -> 2.5539163 | R20: 0 | S20: 0 | T20: =(R20+S20)/J20*100 -> 0 | U20: 13.3 | V20: =IF(E20="","",LN(E20)) | W20: =IF(K20="","",LN(K20)) | X20: =IF(Q20="","",LN(Q20)) -> 0.93762798 | Y20: =LN(1+U20) -> 2.6602595 | Z20: =IF(B20=2017,"",W-43) | AA20: =IF(B20=2017,"",L-43) | AB20: =IF(B20=2017,"",M-43) | AC20: =IF(B20=2017,"",N-43) | AD20: =IF(B20=2017,"",O-43) | AE20: =IF(B20=2017,"",X-43) | AF20: =IF(B20=2017,"",T-43) | AG20: =IF(B20=2017,"",Y-43)
A21: Hà Nam | B21: 2017 | C21: ĐBSH | D21: =IF(OR(C21="ĐNB",C21="ĐBSH"),1,0) -> 1 | E21: 29.3 | F21: 15.8 | G21: 40.4 | H21: 20.8 | I21: 61.5 | J21: 839.8 | L21: 3.991 | M21: 16.46 | N21: 18.1 | P21: 10547.9 | Q21: =IF(P21="","",P21/J21) -> 12.560014 | R21: 8 | S21: 2 | T21: =(R21+S21)/J21*100 -> 1.1907597 | U21: 2902.6 | V21: =IF(E21="","",LN(E21)) -> 3.3775875 | W21: =IF(K21="","",LN(K21)) | X21: =IF(Q21="","",LN(Q21)) -> 2.5305183 | Y21: =LN(1+U21) -> 7.9737066 | Z21: =IF(B21=2017,"",W-42) | AA21: =IF(B21=2017,"",L-42) | AB21: =IF(B21=2017,"",M-42) | AC21: =IF(B21=2017,"",N-42) | AD21: =IF(B21=2017,"",O-42) | AE21: =IF(B21=2017,"",X-42) | AF21: =IF(B21=2017,"",T-42) | AG21: =IF(B21=2017,"",Y-42)
A22: Hà Nội | B22: 2017 | C22: ĐBSH | D22: =IF(OR(C22="ĐNB",C22="ĐBSH"),1,0) -> 1 | E22: 75.8 | F22: 93.7 | G22: 69.2 | H22: 64.4 | I22: 76 | J22: 7742.2 | L22: 17.305 | M22: 49.21 | N22: 44.2 | P22: 102314.7 | Q22: =IF(P22="","",P22/J22) -> 13.215197 | R22: 124 | S22: 22 | T22: =(R22+S22)/J22*100 -> 1.8857689 | U22: 3569.8 | V22: =IF(E22="","",LN(E22)) -> 4.3280983 | W22: =IF(K22="","",LN(K22)) | X22: =IF(Q22="","",LN(Q22)) -> 2.5813675 | Y22: =LN(1+U22) -> 8.1805449 | Z22: =IF(B22=2017,"",W-41) | AA22: =IF(B22=2017,"",L-41) | AB22: =IF(B22=2017,"",M-41) | AC22: =IF(B22=2017,"",N-41) | AD22: =IF(B22=2017,"",O-41) | AE22: =IF(B22=2017,"",X-41) | AF22: =IF(B22=2017,"",T-41) | AG22: =IF(B22=2017,"",Y-41)
A23: Hà Tĩnh | B23: 2017 | C23: BTB&DHMT | D23: =IF(OR(C23="ĐNB",C23="ĐBSH"),1,0) -> 0 | E23: 27.1 | F23: 11.9 | G23: 33.2 | H23: 25 | I23: 60.8 | J23: 1274.2 | L23: 3.27 | M23: 18.62 | N23: 21.5 | P23: 31877.7 | Q23: =IF(P23="","",P23/J23) -> 25.017815 | R23: 5 | S23: 1 | T23: =(R23+S23)/J23*100 -> 0.47088369 | U23: 9114.1 | V23: =IF(E23="","",LN(E23)) -> 3.2995337 | W23: =IF(K23="","",LN(K23)) | X23: =IF(Q23="","",LN(Q23)) -> 3.2195882 | Y23: =LN(1+U23) -> 9.1176877 | Z23: =IF(B23=2017,"",W-40) | AA23: =IF(B23=2017,"",L-40) | AB23: =IF(B23=2017,"",M-40) | AC23: =IF(B23=2017,"",N-40) | AD23: =IF(B23=2017,"",O-40) | AE23: =IF(B23=2017,"",X-40) | AF23: =IF(B23=2017,"",T-40) | AG23: =IF(B23=2017,"",Y-40)
A24: Hòa Bình | B24: 2017 | C24: TDMNPB | D24: =IF(OR(C24="ĐNB",C24="ĐBSH"),1,0) -> 0 | E24: 25.1 | F24: 10.8 | G24: 30.1 | H24: 22.3 | I24: 61 | J24: 845 | L24: 2.368 | M24: 15.59 | N24: 17.8 | P24: 7461.8 | Q24: =IF(P24="","",P24/J24) -> 8.8305325 | R24: 4 | S24: 2 | T24: =(R24+S24)/J24*100 -> 0.71005917 | U24: 664.1 | V24: =IF(E24="","",LN(E24)) -> 3.2228678 | W24: =IF(K24="","",LN(K24)) | X24: =IF(Q24="","",LN(Q24)) -> 2.1782153 | Y24: =LN(1+U24) -> 6.4999374 | Z24: =IF(B24=2017,"",W-39) | AA24: =IF(B24=2017,"",L-39) | AB24: =IF(B24=2017,"",M-39) | AC24: =IF(B24=2017,"",N-39) | AD24: =IF(B24=2017,"",O-39) | AE24: =IF(B24=2017,"",X-39) | AF24: =IF(B24=2017,"",T-39) | AG24: =IF(B24=2017,"",Y-39)
A25: Hưng Yên | B25: 2017 | C25: ĐBSH | D25: =IF(OR(C25="ĐNB",C25="ĐBSH"),1,0) -> 1 | E25: 28 | F25: 14.2 | G25: 36.3 | H25: 21 | I25: 65.8 | J25: 1228.8 | L25: 4.736 | M25: 12.17 | N25: 19.9 | P25: 23965.2 | Q25: =IF(P25="","",P25/J25) -> 19.50293 | R25: 10 | S25: 0 | T25: =(R25+S25)/J25*100 -> 0.81380208 | U25: 3452.5 | V25: =IF(E25="","",LN(E25)) -> 3.3322045 | W25: =IF(K25="","",LN(K25)) | X25: =IF(Q25="","",LN(Q25)) -> 2.9705647 | Y25: =LN(1+U25) -> 8.1471435 | Z25: =IF(B25=2017,"",W-38) | AA25: =IF(B25=2017,"",L-38) | AB25: =IF(B25=2017,"",M-38) | AC25: =IF(B25=2017,"",N-38) | AD25: =IF(B25=2017,"",O-38) | AE25: =IF(B25=2017,"",X-38) | AF25: =IF(B25=2017,"",T-38) | AG25: =IF(B25=2017,"",Y-38)
A26: Hải Dương | B26: 2017 | C26: ĐBSH | D26: =IF(OR(C26="ĐNB",C26="ĐBSH"),1,0) -> 1 | E26: 34.6 | F26: 15.3 | G26: 54.9 | H26: 21.2 | I26: 71.8 | J26: 1850.6 | L26: 4.013 | M26: 23.97 | N26: 20.8 | P26: 32632.8 | Q26: =IF(P26="","",P26/J26) -> 17.633632 | R26: 37 | S26: 2 | T26: =(R26+S26)/J26*100 -> 2.1074246 | U26: 4240.3 | V26: =IF(E26="","",LN(E26)) -> 3.5438537 | W26: =IF(K26="","",LN(K26)) | X26: =IF(Q26="","",LN(Q26)) -> 2.869808 | Y26: =LN(1+U26) -> 8.3526251 | Z26: =IF(B26=2017,"",W-37) | AA26: =IF(B26=2017,"",L-37) | AB26: =IF(B26=2017,"",M-37) | AC26: =IF(B26=2017,"",N-37) | AD26: =IF(B26=2017,"",O-37) | AE26: =IF(B26=2017,"",X-37) | AF26: =IF(B26=2017,"",T-37) | AG26: =IF(B26=2017,"",Y-37)
A27: Hải Phòng | B27: 2017 | C27: ĐBSH | D27: =IF(OR(C27="ĐNB",C27="ĐBSH"),1,0) -> 1 | E27: 42.2 | F27: 22.1 | G27: 61.6 | H27: 32.3 | I27: 73.9 | J27: 2001.4 | L27: 10.791 | M27: 45.69 | N27: 33.8 | P27: 64855.4 | Q27: =IF(P27="","",P27/J27) -> 32.405016 | R27: 24 | S27: 11 | T27: =(R27+S27)/J27*100 -> 1.7487759 | U27: 7599.1 | V27: =IF(E27="","",LN(E27)) -> 3.7424202 | W27: =IF(K27="","",LN(K27)) | X27: =IF(Q27="","",LN(Q27)) -> 3.4783132 | Y27: =LN(1+U27) -> 8.9359167 | Z27: =IF(B27=2017,"",W-36) | AA27: =IF(B27=2017,"",L-36) | AB27: =IF(B27=2017,"",M-36) | AC27: =IF(B27=2017,"",N-36) | AD27: =IF(B27=2017,"",O-36) | AE27: =IF(B27=2017,"",X-36) | AF27: =IF(B27=2017,"",T-36) | AG27: =IF(B27=2017,"",Y-36)
A28: Hậu Giang | B28: 2017 | C28: ĐBSCL | D28: =IF(OR(C28="ĐNB",C28="ĐBSH"),1,0) -> 0 | J28: 737.3 | L28: 2.5 | M28: 24.26 | N28: 9 | P28: 1923.6 | Q28: =IF(P28="","",P28/J28) -> 2.6089787 | R28: 5 | S28: 1 | T28: =(R28+S28)/J28*100 -> 0.81378001 | U28: 1076.4 | V28: =IF(E28="","",LN(E28)) | W28: =IF(K28="","",LN(K28)) | X28: =IF(Q28="","",LN(Q28)) -> 0.95895884 | Y28: =LN(1+U28) -> 6.982306 | Z28: =IF(B28=2017,"",W-35) | AA28: =IF(B28=2017,"",L-35) | AB28: =IF(B28=2017,"",M-35) | AC28: =IF(B28=2017,"",N-35) | AD28: =IF(B28=2017,"",O-35) | AE28: =IF(B28=2017,"",X-35) | AF28: =IF(B28=2017,"",T-35) | AG28: =IF(B28=2017,"",Y-35)
A29: Khánh Hòa | B29: 2017 | C29: BTB&DHMT | D29: =IF(OR(C29="ĐNB",C29="ĐBSH"),1,0) -> 0 | E29: 34.6 | F29: 21.5 | G29: 47.3 | H29: 25.9 | I29: 62 | J29: 1216.3 | L29: 7.732 | M29: 41.78 | N29: 18.7 | P29: 21747.8 | Q29: =IF(P29="","",P29/J29) -> 17.880293 | R29: 24 | S29: 4 | T29: =(R29+S29)/J29*100 -> 2.3020636 | U29: 3432.6 | V29: =IF(E29="","",LN(E29)) -> 3.5438537 | W29: =IF(K29="","",LN(K29)) | X29: =IF(Q29="","",LN(Q29)) -> 2.8836991 | Y29: =LN(1+U29) -> 8.1413646 | Z29: =IF(B29=2017,"",W-34) | AA29: =IF(B29=2017,"",L-34) | AB29: =IF(B29=2017,"",M-34) | AC29: =IF(B29=2017,"",N-34) | AD29: =IF(B29=2017,"",O-34) | AE29: =IF(B29=2017,"",X-34) | AF29: =IF(B29=2017,"",T-34) | AG29: =IF(B29=2017,"",Y-34)
A30: Kiên Giang | B30: 2017 | C30: ĐBSCL | D30: =IF(OR(C30="ĐNB",C30="ĐBSH"),1,0) -> 0 | E30: 27.5 | F30: 14.9 | G30: 35 | H30: 21.4 | I30: 61 | J30: 1712.9 | L30: 3.959 | M30: 28.06 | N30: 10.8 | P30: 3218 | Q30: =IF(P30="","",P30/J30) -> 1.8786853 | R30: 7 | S30: 1 | T30: =(R30+S30)/J30*100 -> 0.46704419 | U30: 2552 | V30: =IF(E30="","",LN(E30)) -> 3.314186 | W30: =IF(K30="","",LN(K30)) | X30: =IF(Q30="","",LN(Q30)) -> 0.63057221 | Y30: =LN(1+U30) -> 7.8450244 | Z30: =IF(B30=2017,"",W-33) | AA30: =IF(B30=2017,"",L-33) | AB30: =IF(B30=2017,"",M-33) | AC30: =IF(B30=2017,"",N-33) | AD30: =IF(B30=2017,"",O-33) | AE30: =IF(B30=2017,"",X-33) | AF30: =IF(B30=2017,"",T-33) | AG30: =IF(B30=2017,"",Y-33)
A31: Kon Tum | B31: 2017 | C31: TN | D31: =IF(OR(C31="ĐNB",C31="ĐBSH"),1,0) -> 0 | E31: 24.2 | F31: 15.5 | G31: 26.8 | H31: 20.6 | I31: 53 | J31: 520.1 | L31: 2.982 | M31: 32.26 | N31: 16.6 | P31: 4856.9 | Q31: =IF(P31="","",P31/J31) -> 9.3383965 | R31: 2 | S31: 0 | T31: =(R31+S31)/J31*100 -> 0.38454143 | U31: 158.2 | V31: =IF(E31="","",LN(E31)) -> 3.1863526 | W31: =IF(K31="","",LN(K31)) | X31: =IF(Q31="","",LN(Q31)) -> 2.2341346 | Y31: =LN(1+U31) -> 5.0701613 | Z31: =IF(B31=2017,"",W-32) | AA31: =IF(B31=2017,"",L-32) | AB31: =IF(B31=2017,"",M-32) | AC31: =IF(B31=2017,"",N-32) | AD31: =IF(B31=2017,"",O-32) | AE31: =IF(B31=2017,"",X-32) | AF31: =IF(B31=2017,"",T-32) | AG31: =IF(B31=2017,"",Y-32)
A32: Lai Châu | B32: 2017 | C32: TDMNPB | D32: =IF(OR(C32="ĐNB",C32="ĐBSH"),1,0) -> 0 | J32: 444.5 | L32: 2.468 | M32: 14.67 | N32: 14.4 | P32: 1193.4 | Q32: =IF(P32="","",P32/J32) -> 2.6848144 | R32: 5 | S32: 2 | T32: =(R32+S32)/J32*100 -> 1.5748031 | U32: 9 | V32: =IF(E32="","",LN(E32)) | W32: =IF(K32="","",LN(K32)) | X32: =IF(Q32="","",LN(Q32)) -> 0.9876116 | Y32: =LN(1+U32) -> 2.3025851 | Z32: =IF(B32=2017,"",W-31) | AA32: =IF(B32=2017,"",L-31) | AB32: =IF(B32=2017,"",M-31) | AC32: =IF(B32=2017,"",N-31) | AD32: =IF(B32=2017,"",O-31) | AE32: =IF(B32=2017,"",X-31) | AF32: =IF(B32=2017,"",T-31) | AG32: =IF(B32=2017,"",Y-31)
A33: Long An | B33: 2017 | C33: ĐBSCL | D33: =IF(OR(C33="ĐNB",C33="ĐBSH"),1,0) -> 0 | E33: 27.9 | F33: 14.8 | G33: 35 | H33: 23.2 | I33: 59.6 | J33: 1662.3 | L33: 4.711 | M33: 16.35 | N33: 14.6 | P33: 5337.8 | Q33: =IF(P33="","",P33/J33) -> 3.2110931 | R33: 5 | S33: 0 | T33: =(R33+S33)/J33*100 -> 0.30078806 | U33: 4193.4 | V33: =IF(E33="","",LN(E33)) -> 3.3286267 | W33: =IF(K33="","",LN(K33)) | X33: =IF(Q33="","",LN(Q33)) -> 1.1666114 | Y33: =LN(1+U33) -> 8.3415056 | Z33: =IF(B33=2017,"",W-30) | AA33: =IF(B33=2017,"",L-30) | AB33: =IF(B33=2017,"",M-30) | AC33: =IF(B33=2017,"",N-30) | AD33: =IF(B33=2017,"",O-30) | AE33: =IF(B33=2017,"",X-30) | AF33: =IF(B33=2017,"",T-30) | AG33: =IF(B33=2017,"",Y-30)
A34: Lào Cai | B34: 2017 | C34: TDMNPB | D34: =IF(OR(C34="ĐNB",C34="ĐBSH"),1,0) -> 0 | E34: 26.6 | F34: 12.3 | G34: 35 | H34: 18.6 | I34: 68.5 | J34: 708.6 | L34: 3.638 | M34: 22.86 | N34: 19.1 | P34: 3955.3 | Q34: =IF(P34="","",P34/J34) -> 5.5818515 | R34: 13 | S34: 1 | T34: =(R34+S34)/J34*100 -> 1.9757268 | U34: 819.4 | V34: =IF(E34="","",LN(E34)) -> 3.2809112 | W34: =IF(K34="","",LN(K34)) | X34: =IF(Q34="","",LN(Q34)) -> 1.7195205 | Y34: =LN(1+U34) -> 6.709792 | Z34: =IF(B34=2017,"",W-29) | AA34: =IF(B34=2017,"",L-29) | AB34: =IF(B34=2017,"",M-29) | AC34: =IF(B34=2017,"",N-29) | AD34: =IF(B34=2017,"",O-29) | AE34: =IF(B34=2017,"",X-29) | AF34: =IF(B34=2017,"",T-29) | AG34: =IF(B34=2017,"",Y-29)
A35: Lâm Đồng | B35: 2017 | C35: TN | D35: =IF(OR(C35="ĐNB",C35="ĐBSH"),1,0) -> 0 | E35: 27.2 | F35: 16.6 | G35: 30 | H35: 24.2 | I35: 60 | J35: 1281.3 | L35: 4.298 | M35: 38.99 | N35: 15 | P35: 11291.5 | Q35: =IF(P35="","",P35/J35) -> 8.8125341 | R35: 3 | S35: 1 | T35: =(R35+S35)/J35*100 -> 0.31218294 | U35: 410.4 | V35: =IF(E35="","",LN(E35)) -> 3.303217 | W35: =IF(K35="","",LN(K35)) | X35: =IF(Q35="","",LN(Q35)) -> 2.176175 | Y35: =LN(1+U35) -> 6.019566 | Z35: =IF(B35=2017,"",W-28) | AA35: =IF(B35=2017,"",L-28) | AB35: =IF(B35=2017,"",M-28) | AC35: =IF(B35=2017,"",N-28) | AD35: =IF(B35=2017,"",O-28) | AE35: =IF(B35=2017,"",X-28) | AF35: =IF(B35=2017,"",T-28) | AG35: =IF(B35=2017,"",Y-28)
A36: Lạng Sơn | B36: 2017 | C36: TDMNPB | D36: =IF(OR(C36="ĐNB",C36="ĐBSH"),1,0) -> 0 | E36: 21.2 | F36: 13.4 | G36: 27.6 | H36: 12.7 | I36: 50.5 | J36: 768.7 | L36: 2.092 | M36: 20.22 | N36: 15.5 | P36: 5710.6 | Q36: =IF(P36="","",P36/J36) -> 7.4289059 | R36: 2 | S36: 1 | T36: =(R36+S36)/J36*100 -> 0.39026929 | U36: 294.4 | V36: =IF(E36="","",LN(E36)) -> 3.0540012 | W36: =IF(K36="","",LN(K36)) | X36: =IF(Q36="","",LN(Q36)) -> 2.0053786 | Y36: =LN(1+U36) -> 5.6883304 | Z36: =IF(B36=2017,"",W-27) | AA36: =IF(B36=2017,"",L-27) | AB36: =IF(B36=2017,"",M-27) | AC36: =IF(B36=2017,"",N-27) | AD36: =IF(B36=2017,"",O-27) | AE36: =IF(B36=2017,"",X-27) | AF36: =IF(B36=2017,"",T-27) | AG36: =IF(B36=2017,"",Y-27)
A37: Nam Định | B37: 2017 | C37: ĐBSH | D37: =IF(OR(C37="ĐNB",C37="ĐBSH"),1,0) -> 1 | E37: 33.3 | F37: 18.3 | G37: 48.3 | H37: 19.6 | I37: 74.5 | J37: 1788.2 | L37: 2.821 | M37: 17.7 | N37: 15.3 | P37: 10363.7 | Q37: =IF(P37="","",P37/J37) -> 5.7956045 | R37: 12 | S37: 0 | T37: =(R37+S37)/J37*100 -> 0.67106588 | U37: 1744 | V37: =IF(E37="","",LN(E37)) -> 3.5055574 | W37: =IF(K37="","",LN(K37)) | X37: =IF(Q37="","",LN(Q37)) -> 1.7570998 | Y37: =LN(1+U37) -> 7.4645098 | Z37: =IF(B37=2017,"",W-26) | AA37: =IF(B37=2017,"",L-26) | AB37: =IF(B37=2017,"",M-26) | AC37: =IF(B37=2017,"",N-26) | AD37: =IF(B37=2017,"",O-26) | AE37: =IF(B37=2017,"",X-26) | AF37: =IF(B37=2017,"",T-26) | AG37: =IF(B37=2017,"",Y-26)
A38: Nghệ An | B38: 2017 | C38: BTB&DHMT | D38: =IF(OR(C38="ĐNB",C38="ĐBSH"),1,0) -> 0 | E38: 30.7 | F38: 14.8 | G38: 36.3 | H38: 26.8 | I38: 72.8 | J38: 3246.7 | L38: 3.529 | M38: 14.73 | N38: 19.9 | P38: 63332.9 | Q38: =IF(P38="","",P38/J38) -> 19.506853 | R38: 44 | S38: 7 | T38: =(R38+S38)/J38*100 -> 1.5708258 | U38: 560.8 | V38: =IF(E38="","",LN(E38)) -> 3.4242627 | W38: =IF(K38="","",LN(K38)) | X38: =IF(Q38="","",LN(Q38)) -> 2.9707658 | Y38: =LN(1+U38) -> 6.3311459 | Z38: =IF(B38=2017,"",W-25) | AA38: =IF(B38=2017,"",L-25) | AB38: =IF(B38=2017,"",M-25) | AC38: =IF(B38=2017,"",N-25) | AD38: =IF(B38=2017,"",O-25) | AE38: =IF(B38=2017,"",X-25) | AF38: =IF(B38=2017,"",T-25) | AG38: =IF(B38=2017,"",Y-25)
A39: Ninh Bình | B39: 2017 | C39: ĐBSH | D39: =IF(OR(C39="ĐNB",C39="ĐBSH"),1,0) -> 1 | E39: 29.6 | F39: 13.3 | G39: 40.3 | H39: 22.1 | I39: 69.3 | J39: 965.4 | L39: 3.677 | M39: 20.21 | N39: 26.4 | P39: 25000.8 | Q39: =IF(P39="","",P39/J39) -> 25.89683 | R39: 9 | S39: 3 | T39: =(R39+S39)/J39*100 -> 1.2430081 | U39: 1311.7 | V39: =IF(E39="","",LN(E39)) -> 3.3877744 | W39: =IF(K39="","",LN(K39)) | X39: =IF(Q39="","",LN(Q39)) -> 3.2541206 | Y39: =LN(1+U39) -> 7.1798414 | Z39: =IF(B39=2017,"",W-24) | AA39: =IF(B39=2017,"",L-24) | AB39: =IF(B39=2017,"",M-24) | AC39: =IF(B39=2017,"",N-24) | AD39: =IF(B39=2017,"",O-24) | AE39: =IF(B39=2017,"",X-24) | AF39: =IF(B39=2017,"",T-24) | AG39: =IF(B39=2017,"",Y-24)
A40: Ninh Thuận | B40: 2017 | C40: BTB&DHMT | D40: =IF(OR(C40="ĐNB",C40="ĐBSH"),1,0) -> 0 | E40: 25.3 | F40: 10.8 | G40: 39.2 | H40: 18.9 | I40: 46 | J40: 585.4 | L40: 3.329 | M40: 35.82 | N40: 15.1 | P40: 6053.3 | Q40: =IF(P40="","",P40/J40) -> 10.340451 | R40: 4 | S40: 1 | T40: =(R40+S40)/J40*100 -> 0.85411684 | U40: 2225 | V40: =IF(E40="","",LN(E40)) -> 3.2308044 | W40: =IF(K40="","",LN(K40)) | X40: =IF(Q40="","",LN(Q40)) -> 2.3360635 | Y40: =LN(1+U40) -> 7.7079615 | Z40: =IF(B40=2017,"",W-23) | AA40: =IF(B40=2017,"",L-23) | AB40: =IF(B40=2017,"",M-23) | AC40: =IF(B40=2017,"",N-23) | AD40: =IF(B40=2017,"",O-23) | AE40: =IF(B40=2017,"",X-23) | AF40: =IF(B40=2017,"",T-23) | AG40: =IF(B40=2017,"",Y-23)
A41: Phú Thọ | B41: 2017 | C41: TDMNPB | D41: =IF(OR(C41="ĐNB",C41="ĐBSH"),1,0) -> 0 | E41: 28.5 | F41: 13.2 | G41: 38.2 | H41: 23.7 | I41: 60.1 | J41: 1430.5 | L41: 2.987 | M41: 18.32 | N41: 21.8 | P41: 24416.5 | Q41: =IF(P41="","",P41/J41) -> 17.068508 | R41: 14 | S41: 2 | T41: =(R41+S41)/J41*100 -> 1.11849 | U41: 758.3 | V41: =IF(E41="","",LN(E41)) -> 3.3499041 | W41: =IF(K41="","",LN(K41)) | X41: =IF(Q41="","",LN(Q41)) -> 2.8372351 | Y41: =LN(1+U41) -> 6.632397 | Z41: =IF(B41=2017,"",W-22) | AA41: =IF(B41=2017,"",L-22) | AB41: =IF(B41=2017,"",M-22) | AC41: =IF(B41=2017,"",N-22) | AD41: =IF(B41=2017,"",O-22) | AE41: =IF(B41=2017,"",X-22) | AF41: =IF(B41=2017,"",T-22) | AG41: =IF(B41=2017,"",Y-22)
...

Sheet 2_Bang1_Mo_ta
A1: BẢNG 1. Thống kê mô tả (gộp 2017–2024; N = số ô không trống)
A3: Biến | B3: Cột trong 1_Du_lieu | C3: N | D3: Trung bình | E3: Độ lệch chuẩn | F3: Nhỏ nhất | G3: Lớn nhất
A4: Chỉ số TMĐT tổng hợp (EBI) | B4: E | C4: =COUNT('1_Du_lieu'!$E$5:$E$508) -> 445 | D4: =AVERAGE('1_Du_lieu'!$E$5:$E$508) -> 27.527888 | E4: =_xlfn.STDEV.S('1_Du_lieu'!$E$5:$E$508) -> 16.56187 | F4: =MIN('1_Du_lieu'!$E$5:$E$508) -> 3.98 | G4: =MAX('1_Du_lieu'!$E$5:$E$508) -> 90.6
A5: Trụ cột NNL&HT | B5: F | C5: =COUNT('1_Du_lieu'!$F$5:$F$508) -> 445 | D5: =AVERAGE('1_Du_lieu'!$F$5:$F$508) -> 25.856719 | E5: =_xlfn.STDEV.S('1_Du_lieu'!$F$5:$F$508) -> 15.785477 | F5: =MIN('1_Du_lieu'!$F$5:$F$508) -> 8.5 | G5: =MAX('1_Du_lieu'!$F$5:$F$508) -> 98.5
A6: Trụ cột B2C | B6: G | C6: =COUNT('1_Du_lieu'!$G$5:$G$508) -> 445 | D6: =AVERAGE('1_Du_lieu'!$G$5:$G$508) -> 30.158449 | E6: =_xlfn.STDEV.S('1_Du_lieu'!$G$5:$G$508) -> 19.247672 | F6: =MIN('1_Du_lieu'!$G$5:$G$508) -> 2.04 | G6: =MAX('1_Du_lieu'!$G$5:$G$508) -> 89.8
A7: Trụ cột B2B | B7: H | C7: =COUNT('1_Du_lieu'!$H$5:$H$508) -> 445 | D7: =AVERAGE('1_Du_lieu'!$H$5:$H$508) -> 22.825371 | E7: =_xlfn.STDEV.S('1_Du_lieu'!$H$5:$H$508) -> 15.540944 | F7: =MIN('1_Du_lieu'!$H$5:$H$508) -> 1.86 | G7: =MAX('1_Du_lieu'!$H$5:$H$508) -> 96
A8: Trụ cột G2B (2017–2020) | B8: I | C8: =COUNT('1_Du_lieu'!$I$5:$I$508) -> 217 | D8: =AVERAGE('1_Du_lieu'!$I$5:$I$508) -> 64.202765 | E8: =_xlfn.STDEV.S('1_Du_lieu'!$I$5:$I$508) -> 8.8390229 | F8: =MIN('1_Du_lieu'!$I$5:$I$508) -> 43 | G8: =MAX('1_Du_lieu'!$I$5:$I$508) -> 86
A9: GRDP bình quân đầu người (tr.đ) | B9: K | C9: =COUNT('1_Du_lieu'!$K$5:$K$508) -> 441 | D9: =AVERAGE('1_Du_lieu'!$K$5:$K$508) -> 76.918821 | E9: =_xlfn.STDEV.S('1_Du_lieu'!$K$5:$K$508) -> 46.28039 | F9: =MIN('1_Du_lieu'!$K$5:$K$508) -> 26.1 | G9: =MAX('1_Du_lieu'!$K$5:$K$508) -> 372.1
A10: Mật độ doanh nghiệp (DN/1.000 dân) | B10: L | C10: =COUNT('1_Du_lieu'!$L$5:$L$508) -> 504 | D10: =AVERAGE('1_Du_lieu'!$L$5:$L$508) -> 5.1940417 | E10: =_xlfn.STDEV.S('1_Du_lieu'!$L$5:$L$508) -> 4.6091139 | F10: =MIN('1_Du_lieu'!$L$5:$L$508) -> 1.344 | G10: =MAX('1_Du_lieu'!$L$5:$L$508) -> 29.287
A11: Tỷ lệ dân số thành thị (%) | B11: M | C11: =COUNT('1_Du_lieu'!$M$5:$M$508) -> 504 | D11: =AVERAGE('1_Du_lieu'!$M$5:$M$508) -> 30.363591 | E11: =_xlfn.STDEV.S('1_Du_lieu'!$M$5:$M$508) -> 17.251925 | F11: =MIN('1_Du_lieu'!$M$5:$M$508) -> 9.8 | G11: =MAX('1_Du_lieu'!$M$5:$M$508) -> 87.81
A12: Tỷ lệ LĐ 15+ qua đào tạo (%) | B12: N | C12: =COUNT('1_Du_lieu'!$N$5:$N$508) -> 504 | D12: =AVERAGE('1_Du_lieu'!$N$5:$N$508) -> 22.068452 | E12: =_xlfn.STDEV.S('1_Du_lieu'!$N$5:$N$508) -> 8.3342223 | F12: =MIN('1_Du_lieu'!$N$5:$N$508) -> 8.2 | G12: =MAX('1_Du_lieu'!$N$5:$N$508) -> 53.9
A13: Tỷ lệ hộ có máy tính (%) | B13: O | C13: =COUNT('1_Du_lieu'!$O$5:$O$508) -> 378 | D13: =AVERAGE('1_Du_lieu'!$O$5:$O$508) -> 21.265344 | E13: =_xlfn.STDEV.S('1_Du_lieu'!$O$5:$O$508) -> 8.8983198 | F13: =MIN('1_Du_lieu'!$O$5:$O$508) -> 4.3 | G13: =MAX('1_Du_lieu'!$O$5:$O$508) -> 58.1
A14: Hàng hóa đường bộ/người (tấn) | B14: Q | C14: =COUNT('1_Du_lieu'!$Q$5:$Q$508) -> 496 | D14: =AVERAGE('1_Du_lieu'!$Q$5:$Q$508) -> 13.229175 | E14: =_xlfn.STDEV.S('1_Du_lieu'!$Q$5:$Q$508) -> 11.423691 | F14: =MIN('1_Du_lieu'!$Q$5:$Q$508) -> 0.37903091 | G14: =MAX('1_Du_lieu'!$Q$5:$Q$508) -> 68.197136
A15: Siêu thị + TTTM/100.000 dân | B15: T | C15: =COUNT('1_Du_lieu'!$T$5:$T$508) -> 504 | D15: =AVERAGE('1_Du_lieu'!$T$5:$T$508) -> 1.2049828 | E15: =_xlfn.STDEV.S('1_Du_lieu'!$T$5:$T$508) -> 1.1632725 | F15: =MIN('1_Du_lieu'!$T$5:$T$508) -> 0 | G15: =MAX('1_Du_lieu'!$T$5:$T$508) -> 6.9992821
A16: FDI lũy kế/người (USD) | B16: U | C16: =COUNT('1_Du_lieu'!$U$5:$U$508) -> 504 | D16: =AVERAGE('1_Du_lieu'!$U$5:$U$508) -> 3354.344 | E16: =_xlfn.STDEV.S('1_Du_lieu'!$U$5:$U$508) -> 4640.2111 | F16: =MIN('1_Du_lieu'!$U$5:$U$508) -> 3 | G16: =MAX('1_Du_lieu'!$U$5:$U$508) -> 30546.5

Sheet 3_Bang2_EBI_tuong_doi
A1: EBI TƯƠNG ĐỐI = EBI / trung bình các tỉnh có số liệu trong năm × 100
A2: Trung bình năm t tính bằng AVERAGE trên khối 63 dòng của năm t trong 1_Du_lieu (ô trống bị bỏ qua, nên mẫu số là số tỉnh có EBI).
A4: Tỉnh | B4: Năm | C4: Vùng | D4: Giai đoạn | E4: EBI | F4: Trung bình năm (N tỉnh có EBI) | G4: EBI tương đối | H4: NNL&HT tương đối | I4: B2C tương đối | J4: B2B tương đối | K4: Lõi
A5: An Giang | B5: 2017 | C5: ='1_Du_lieu'!C5 -> ĐBSCL | D5: =IF(B5<=2020,"2017–2020","2021–2024") -> 2017–2020 | E5: ='1_Du_lieu'!E5 -> 27.2 | F5: =AVERAGE('1_Du_lieu'!$E$5:$E$67) -> 31.157407 | G5: =E5/F5*100 -> 87.298663 | H5: ='1_Du_lieu'!F5/AVERAGE('1_Du_lieu'!$F$5:$F$67)*100 -> 70.210758 | I5: ='1_Du_lieu'!G5/AVERAGE('1_Du_lieu'!$G$5:$G$67)*100 -> 98.563296 | J5: ='1_Du_lieu'!H5/AVERAGE('1_Du_lieu'!$H$5:$H$67)*100 -> 59.844084 | K5: ='1_Du_lieu'!D5 -> 0
A6: Bà Rịa - Vũng Tàu | B6: 2017 | C6: ='1_Du_lieu'!C6 -> ĐNB | D6: =IF(B6<=2020,"2017–2020","2021–2024") -> 2017–2020 | E6: ='1_Du_lieu'!E6 -> 37.8 | F6: =AVERAGE('1_Du_lieu'!$E$5:$E$67) -> 31.157407 | G6: =E6/F6*100 -> 121.31947 | H6: ='1_Du_lieu'!F6/AVERAGE('1_Du_lieu'!$F$5:$F$67)*100 -> 120.60396 | I6: ='1_Du_lieu'!G6/AVERAGE('1_Du_lieu'!$G$5:$G$67)*100 -> 139.06208 | J6: ='1_Du_lieu'!H6/AVERAGE('1_Du_lieu'!$H$5:$H$67)*100 -> 118.0373 | K6: ='1_Du_lieu'!D6 -> 1
A7: Bình Dương | B7: 2017 | C7: ='1_Du_lieu'!C7 -> ĐNB | D7: =IF(B7<=2020,"2017–2020","2021–2024") -> 2017–2020 | E7: ='1_Du_lieu'!E7 -> 43 | F7: =AVERAGE('1_Du_lieu'!$E$5:$E$67) -> 31.157407 | G7: =E7/F7*100 -> 138.00892 | H7: ='1_Du_lieu'!F7/AVERAGE('1_Du_lieu'!$F$5:$F$67)*100 -> 120.03775 | I7: ='1_Du_lieu'!G7/AVERAGE('1_Du_lieu'!$G$5:$G$67)*100 -> 151.50447 | J7: ='1_Du_lieu'!H7/AVERAGE('1_Du_lieu'!$H$5:$H$67)*100 -> 151.46744 | K7: ='1_Du_lieu'!D7 -> 1
A8: Bình Phước | B8: 2017 | C8: ='1_Du_lieu'!C8 -> ĐNB | D8: =IF(B8<=2020,"2017–2020","2021–2024") -> 2017–2020 | E8: ='1_Du_lieu'!E8 -> 24 | F8: =AVERAGE('1_Du_lieu'!$E$5:$E$67) -> 31.157407 | G8: =E8/F8*100 -> 77.028232 | H8: ='1_Du_lieu'!F8/AVERAGE('1_Du_lieu'!$F$5:$F$67)*100 -> 62.283737 | I8: ='1_Du_lieu'!G8/AVERAGE('1_Du_lieu'!$G$5:$G$67)*100 -> 85.388994 | J8: ='1_Du_lieu'!H8/AVERAGE('1_Du_lieu'!$H$5:$H$67)*100 -> 73.463773 | K8: ='1_Du_lieu'!D8 -> 1
A9: Bình Thuận | B9: 2017 | C9: ='1_Du_lieu'!C9 -> BTB&DHMT | D9: =IF(B9<=2020,"2017–2020","2021–2024") -> 2017–2020 | E9: ='1_Du_lieu'!E9 -> 29.5 | F9: =AVERAGE('1_Du_lieu'!$E$5:$E$67) -> 31.157407 | G9: =E9/F9*100 -> 94.680535 | H9: ='1_Du_lieu'!F9/AVERAGE('1_Du_lieu'!$F$5:$F$67)*100 -> 82.10129 | I9: ='1_Du_lieu'!G9/AVERAGE('1_Du_lieu'!$G$5:$G$67)*100 -> 101.24695 | J9: ='1_Du_lieu'!H9/AVERAGE('1_Du_lieu'!$H$5:$H$67)*100 -> 90.385203 | K9: ='1_Du_lieu'!D9 -> 0
A10: Bình Định | B10: 2017 | C10: ='1_Du_lieu'!C10 -> BTB&DHMT | D10: =IF(B10<=2020,"2017–2020","2021–2024") -> 2017–2020 | E10: ='1_Du_lieu'!E10 -> 29.9 | F10: =AVERAGE('1_Du_lieu'!$E$5:$E$67) -> 31.157407 | G10: =E10/F10*100 -> 95.964339 | H10: ='1_Du_lieu'!F10/AVERAGE('1_Du_lieu'!$F$5:$F$67)*100 -> 87.763448 | I10: ='1_Du_lieu'!G10/AVERAGE('1_Du_lieu'!$G$5:$G$67)*100 -> 100.02711 | J10: ='1_Du_lieu'!H10/AVERAGE('1_Du_lieu'!$H$5:$H$67)*100 -> 100.70315 | K10: ='1_Du_lieu'!D10 -> 0
A11: Bắc Giang | B11: 2017 | C11: ='1_Du_lieu'!C12 -> TDMNPB | D11: =IF(B11<=2020,"2017–2020","2021–2024") -> 2017–2020 | E11: ='1_Du_lieu'!E12 -> 30 | F11: =AVERAGE('1_Du_lieu'!$E$5:$E$67) -> 31.157407 | G11: =E11/F11*100 -> 96.28529 | H11: ='1_Du_lieu'!F12/AVERAGE('1_Du_lieu'!$F$5:$F$67)*100 -> 65.681032 | I11: ='1_Du_lieu'!G12/AVERAGE('1_Du_lieu'!$G$5:$G$67)*100 -> 98.807265 | J11: ='1_Du_lieu'!H12/AVERAGE('1_Du_lieu'!$H$5:$H$67)*100 -> 103.17946 | K11: ='1_Du_lieu'!D12 -> 0
A12: Bắc Kạn | B12: 2017 | C12: ='1_Du_lieu'!C13 -> TDMNPB | D12: =IF(B12<=2020,"2017–2020","2021–2024") -> 2017–2020 | E12: ='1_Du_lieu'!E13 -> 22.6 | F12: =AVERAGE('1_Du_lieu'!$E$5:$E$67) -> 31.157407 | G12: =E12/F12*100 -> 72.534918 | H12: ='1_Du_lieu'!F13/AVERAGE('1_Du_lieu'!$F$5:$F$67)*100 -> 78.137779 | I12: ='1_Du_lieu'!G13/AVERAGE('1_Du_lieu'!$G$5:$G$67)*100 -> 65.383573 | J12: ='1_Du_lieu'!H13/AVERAGE('1_Du_lieu'!$H$5:$H$67)*100 -> 76.352797 | K12: ='1_Du_lieu'!D13 -> 0
A13: Bắc Ninh | B13: 2017 | C13: ='1_Du_lieu'!C14 -> ĐBSH | D13: =IF(B13<=2020,"2017–2020","2021–2024") -> 2017–2020 | E13: ='1_Du_lieu'!E14 -> 38.9 | F13: =AVERAGE('1_Du_lieu'!$E$5:$E$67) -> 31.157407 | G13: =E13/F13*100 -> 124.84993 | H13: ='1_Du_lieu'!F14/AVERAGE('1_Du_lieu'!$F$5:$F$67)*100 -> 112.11073 | I13: ='1_Du_lieu'!G14/AVERAGE('1_Du_lieu'!$G$5:$G$67)*100 -> 141.01382 | J13: ='1_Du_lieu'!H14/AVERAGE('1_Du_lieu'!$H$5:$H$67)*100 -> 125.0535 | K13: ='1_Du_lieu'!D14 -> 1
A14: Bến Tre | B14: 2017 | C14: ='1_Du_lieu'!C15 -> ĐBSCL | D14: =IF(B14<=2020,"2017–2020","2021–2024") -> 2017–2020 | E14: ='1_Du_lieu'!E15 -> 28.1 | F14: =AVERAGE('1_Du_lieu'!$E$5:$E$67) -> 31.157407 | G14: =E14/F14*100 -> 90.187221 | H14: ='1_Du_lieu'!F15/AVERAGE('1_Du_lieu'!$F$5:$F$67)*100 -> 89.462095 | I14: ='1_Du_lieu'!G15/AVERAGE('1_Du_lieu'!$G$5:$G$67)*100 -> 89.048523 | J14: ='1_Du_lieu'!H15/AVERAGE('1_Du_lieu'!$H$5:$H$67)*100 -> 80.479976 | K14: ='1_Du_lieu'!D15 -> 0
A15: Cà Mau | B15: 2017 | C15: ='1_Du_lieu'!C17 -> ĐBSCL | D15: =IF(B15<=2020,"2017–2020","2021–2024") -> 2017–2020 | E15: ='1_Du_lieu'!E17 -> 21.2 | F15: =AVERAGE('1_Du_lieu'!$E$5:$E$67) -> 31.157407 | G15: =E15/F15*100 -> 68.041605 | H15: ='1_Du_lieu'!F17/AVERAGE('1_Du_lieu'!$F$5:$F$67)*100 -> 62.849953 | I15: ='1_Du_lieu'!G17/AVERAGE('1_Du_lieu'!$G$5:$G$67)*100 -> 58.552453 | J15: ='1_Du_lieu'!H17/AVERAGE('1_Du_lieu'!$H$5:$H$67)*100 -> 76.765515 | K15: ='1_Du_lieu'!D17 -> 0
A16: Cần Thơ | B16: 2017 | C16: ='1_Du_lieu'!C18 -> ĐBSCL | D16: =IF(B16<=2020,"2017–2020","2021–2024") -> 2017–2020 | E16: ='1_Du_lieu'!E18 -> 37.2 | F16: =AVERAGE('1_Du_lieu'!$E$5:$E$67) -> 31.157407 | G16: =E16/F16*100 -> 119.39376 | H16: ='1_Du_lieu'!F18/AVERAGE('1_Du_lieu'!$F$5:$F$67)*100 -> 97.955332 | I16: ='1_Du_lieu'!G18/AVERAGE('1_Du_lieu'!$G$5:$G$67)*100 -> 135.40255 | J16: ='1_Du_lieu'!H18/AVERAGE('1_Du_lieu'!$H$5:$H$67)*100 -> 108.13207 | K16: ='1_Du_lieu'!D18 -> 0
A17: Gia Lai | B17: 2017 | C17: ='1_Du_lieu'!C19 -> TN | D17: =IF(B17<=2020,"2017–2020","2021–2024") -> 2017–2020 | E17: ='1_Du_lieu'!E19 -> 23.7 | F17: =AVERAGE('1_Du_lieu'!$E$5:$E$67) -> 31.157407 | G17: =E17/F17*100 -> 76.065379 | H17: ='1_Du_lieu'!F19/AVERAGE('1_Du_lieu'!$F$5:$F$67)*100 -> 56.621579 | I17: ='1_Du_lieu'!G19/AVERAGE('1_Du_lieu'!$G$5:$G$67)*100 -> 80.509623 | J17: ='1_Du_lieu'!H19/AVERAGE('1_Du_lieu'!$H$5:$H$67)*100 -> 86.670743 | K17: ='1_Du_lieu'!D19 -> 0
A18: Hà Nam | B18: 2017 | C18: ='1_Du_lieu'!C21 -> ĐBSH | D18: =IF(B18<=2020,"2017–2020","2021–2024") -> 2017–2020 | E18: ='1_Du_lieu'!E21 -> 29.3 | F18: =AVERAGE('1_Du_lieu'!$E$5:$E$67) -> 31.157407 | G18: =E18/F18*100 -> 94.038633 | H18: ='1_Du_lieu'!F21/AVERAGE('1_Du_lieu'!$F$5:$F$67)*100 -> 89.462095 | I18: ='1_Du_lieu'!G21/AVERAGE('1_Du_lieu'!$G$5:$G$67)*100 -> 98.563296 | J18: ='1_Du_lieu'!H21/AVERAGE('1_Du_lieu'!$H$5:$H$67)*100 -> 85.845307 | K18: ='1_Du_lieu'!D21 -> 1
A19: Hà Nội | B19: 2017 | C19: ='1_Du_lieu'!C22 -> ĐBSH | D19: =IF(B19<=2020,"2017–2020","2021–2024") -> 2017–2020 | E19: ='1_Du_lieu'!E22 -> 75.8 | F19: =AVERAGE('1_Du_lieu'!$E$5:$E$67) -> 31.157407 | G19: =E19/F19*100 -> 243.28083 | H19: ='1_Du_lieu'!F22/AVERAGE('1_Du_lieu'!$F$5:$F$67)*100 -> 530.5442 | I19: ='1_Du_lieu'!G22/AVERAGE('1_Du_lieu'!$G$5:$G$67)*100 -> 168.82624 | J19: ='1_Du_lieu'!H22/AVERAGE('1_Du_lieu'!$H$5:$H$67)*100 -> 265.79028 | K19: ='1_Du_lieu'!D22 -> 1
A20: Hà Tĩnh | B20: 2017 | C20: ='1_Du_lieu'!C23 -> BTB&DHMT | D20: =IF(B20<=2020,"2017–2020","2021–2024") -> 2017–2020 | E20: ='1_Du_lieu'!E23 -> 27.1 | F20: =AVERAGE('1_Du_lieu'!$E$5:$E$67) -> 31.157407 | G20: =E20/F20*100 -> 86.977712 | H20: ='1_Du_lieu'!F23/AVERAGE('1_Du_lieu'!$F$5:$F$67)*100 -> 67.379679 | I20: ='1_Du_lieu'!G23/AVERAGE('1_Du_lieu'!$G$5:$G$67)*100 -> 80.99756 | J20: ='1_Du_lieu'!H23/AVERAGE('1_Du_lieu'!$H$5:$H$67)*100 -> 103.17946 | K20: ='1_Du_lieu'!D23 -> 0
A21: Hòa Bình | B21: 2017 | C21: ='1_Du_lieu'!C24 -> TDMNPB | D21: =IF(B21<=2020,"2017–2020","2021–2024") -> 2017–2020 | E21: ='1_Du_lieu'!E24 -> 25.1 | F21: =AVERAGE('1_Du_lieu'!$E$5:$E$67) -> 31.157407 | G21: =E21/F21*100 -> 80.558692 | H21: ='1_Du_lieu'!F24/AVERAGE('1_Du_lieu'!$F$5:$F$67)*100 -> 61.151305 | I21: ='1_Du_lieu'!G24/AVERAGE('1_Du_lieu'!$G$5:$G$67)*100 -> 73.434535 | J21: ='1_Du_lieu'!H24/AVERAGE('1_Du_lieu'!$H$5:$H$67)*100 -> 92.036075 | K21: ='1_Du_lieu'!D24 -> 0
A22: Hưng Yên | B22: 2017 | C22: ='1_Du_lieu'!C25 -> ĐBSH | D22: =IF(B22<=2020,"2017–2020","2021–2024") -> 2017–2020 | E22: ='1_Du_lieu'!E25 -> 28 | F22: =AVERAGE('1_Du_lieu'!$E$5:$E$67) -> 31.157407 | G22: =E22/F22*100 -> 89.86627 | H22: ='1_Du_lieu'!F25/AVERAGE('1_Du_lieu'!$F$5:$F$67)*100 -> 80.402642 | I22: ='1_Du_lieu'!G25/AVERAGE('1_Du_lieu'!$G$5:$G$67)*100 -> 88.560586 | J22: ='1_Du_lieu'!H25/AVERAGE('1_Du_lieu'!$H$5:$H$67)*100 -> 86.670743 | K22: ='1_Du_lieu'!D25 -> 1
A23: Hải Dương | B23: 2017 | C23: ='1_Du_lieu'!C26 -> ĐBSH | D23: =IF(B23<=2020,"2017–2020","2021–2024") -> 2017–2020 | E23: ='1_Du_lieu'!E26 -> 34.6 | F23: =AVERAGE('1_Du_lieu'!$E$5:$E$67) -> 31.157407 | G23: =E23/F23*100 -> 111.04903 | H23: ='1_Du_lieu'!F26/AVERAGE('1_Du_lieu'!$F$5:$F$67)*100 -> 86.631016 | I23: ='1_Du_lieu'!G26/AVERAGE('1_Du_lieu'!$G$5:$G$67)*100 -> 133.93874 | J23: ='1_Du_lieu'!H26/AVERAGE('1_Du_lieu'!$H$5:$H$67)*100 -> 87.496179 | K23: ='1_Du_lieu'!D26 -> 1
A24: Hải Phòng | B24: 2017 | C24: ='1_Du_lieu'!C27 -> ĐBSH | D24: =IF(B24<=2020,"2017–2020","2021–2024") -> 2017–2020 | E24: ='1_Du_lieu'!E27 -> 42.2 | F24: =AVERAGE('1_Du_lieu'!$E$5:$E$67) -> 31.157407 | G24: =E24/F24*100 -> 135.44131 | H24: ='1_Du_lieu'!F27/AVERAGE('1_Du_lieu'!$F$5:$F$67)*100 -> 125.13369 | I24: ='1_Du_lieu'!G27/AVERAGE('1_Du_lieu'!$G$5:$G$67)*100 -> 150.28463 | J24: ='1_Du_lieu'!H27/AVERAGE('1_Du_lieu'!$H$5:$H$67)*100 -> 133.30786 | K24: ='1_Du_lieu'!D27 -> 1
A25: Khánh Hòa | B25: 2017 | C25: ='1_Du_lieu'!C29 -> BTB&DHMT | D25: =IF(B25<=2020,"2017–2020","2021–2024") -> 2017–2020 | E25: ='1_Du_lieu'!E29 -> 34.6 | F25: =AVERAGE('1_Du_lieu'!$E$5:$E$67) -> 31.157407 | G25: =E25/F25*100 -> 111.04903 | H25: ='1_Du_lieu'!F29/AVERAGE('1_Du_lieu'!$F$5:$F$67)*100 -> 121.7364 | I25: ='1_Du_lieu'!G29/AVERAGE('1_Du_lieu'!$G$5:$G$67)*100 -> 115.39713 | J25: ='1_Du_lieu'!H29/AVERAGE('1_Du_lieu'!$H$5:$H$67)*100 -> 106.89392 | K25: ='1_Du_lieu'!D29 -> 0
A26: Kiên Giang | B26: 2017 | C26: ='1_Du_lieu'!C30 -> ĐBSCL | D26: =IF(B26<=2020,"2017–2020","2021–2024") -> 2017–2020 | E26: ='1_Du_lieu'!E30 -> 27.5 | F26: =AVERAGE('1_Du_lieu'!$E$5:$E$67) -> 31.157407 | G26: =E26/F26*100 -> 88.261516 | H26: ='1_Du_lieu'!F30/AVERAGE('1_Du_lieu'!$F$5:$F$67)*100 -> 84.366153 | I26: ='1_Du_lieu'!G30/AVERAGE('1_Du_lieu'!$G$5:$G$67)*100 -> 85.388994 | J26: ='1_Du_lieu'!H30/AVERAGE('1_Du_lieu'!$H$5:$H$67)*100 -> 88.321614 | K26: ='1_Du_lieu'!D30 -> 0
A27: Kon Tum | B27: 2017 | C27: ='1_Du_lieu'!C31 -> TN | D27: =IF(B27<=2020,"2017–2020","2021–2024") -> 2017–2020 | E27: ='1_Du_lieu'!E31 -> 24.2 | F27: =AVERAGE('1_Du_lieu'!$E$5:$E$67) -> 31.157407 | G27: =E27/F27*100 -> 77.670134 | H27: ='1_Du_lieu'!F31/AVERAGE('1_Du_lieu'!$F$5:$F$67)*100 -> 87.763448 | I27: ='1_Du_lieu'!G31/AVERAGE('1_Du_lieu'!$G$5:$G$67)*100 -> 65.383573 | J27: ='1_Du_lieu'!H31/AVERAGE('1_Du_lieu'!$H$5:$H$67)*100 -> 85.019872 | K27: ='1_Du_lieu'!D31 -> 0
A28: Long An | B28: 2017 | C28: ='1_Du_lieu'!C33 -> ĐBSCL | D28: =IF(B28<=2020,"2017–2020","2021–2024") -> 2017–2020 | E28: ='1_Du_lieu'!E33 -> 27.9 | F28: =AVERAGE('1_Du_lieu'!$E$5:$E$67) -> 31.157407 | G28: =E28/F28*100 -> 89.545319 | H28: ='1_Du_lieu'!F33/AVERAGE('1_Du_lieu'!$F$5:$F$67)*100 -> 83.799937 | I28: ='1_Du_lieu'!G33/AVERAGE('1_Du_lieu'!$G$5:$G$67)*100 -> 85.388994 | J28: ='1_Du_lieu'!H33/AVERAGE('1_Du_lieu'!$H$5:$H$67)*100 -> 95.750535 | K28: ='1_Du_lieu'!D33 -> 0
A29: Lào Cai | B29: 2017 | C29: ='1_Du_lieu'!C34 -> TDMNPB | D29: =IF(B29<=2020,"2017–2020","2021–2024") -> 2017–2020 | E29: ='1_Du_lieu'!E34 -> 26.6 | F29: =AVERAGE('1_Du_lieu'!$E$5:$E$67) -> 31.157407 | G29: =E29/F29*100 -> 85.372957 | H29: ='1_Du_lieu'!F34/AVERAGE('1_Du_lieu'!$F$5:$F$67)*100 -> 69.644542 | I29: ='1_Du_lieu'!G34/AVERAGE('1_Du_lieu'!$G$5:$G$67)*100 -> 85.388994 | J29: ='1_Du_lieu'!H34/AVERAGE('1_Du_lieu'!$H$5:$H$67)*100 -> 76.765515 | K29: ='1_Du_lieu'!D34 -> 0
A30: Lâm Đồng | B30: 2017 | C30: ='1_Du_lieu'!C35 -> TN | D30: =IF(B30<=2020,"2017–2020","2021–2024") -> 2017–2020 | E30: ='1_Du_lieu'!E35 -> 27.2 | F30: =AVERAGE('1_Du_lieu'!$E$5:$E$67) -> 31.157407 | G30: =E30/F30*100 -> 87.298663 | H30: ='1_Du_lieu'!F35/AVERAGE('1_Du_lieu'!$F$5:$F$67)*100 -> 93.991821 | I30: ='1_Du_lieu'!G35/AVERAGE('1_Du_lieu'!$G$5:$G$67)*100 -> 73.190567 | J30: ='1_Du_lieu'!H35/AVERAGE('1_Du_lieu'!$H$5:$H$67)*100 -> 99.877713 | K30: ='1_Du_lieu'!D35 -> 0
A31: Lạng Sơn | B31: 2017 | C31: ='1_Du_lieu'!C36 -> TDMNPB | D31: =IF(B31<=2020,"2017–2020","2021–2024") -> 2017–2020 | E31: ='1_Du_lieu'!E36 -> 21.2 | F31: =AVERAGE('1_Du_lieu'!$E$5:$E$67) -> 31.157407 | G31: =E31/F31*100 -> 68.041605 | H31: ='1_Du_lieu'!F36/AVERAGE('1_Du_lieu'!$F$5:$F$67)*100 -> 75.872916 | I31: ='1_Du_lieu'!G36/AVERAGE('1_Du_lieu'!$G$5:$G$67)*100 -> 67.335321 | J31: ='1_Du_lieu'!H36/AVERAGE('1_Du_lieu'!$H$5:$H$67)*100 -> 52.415164 | K31: ='1_Du_lieu'!D36 -> 0
A32: Nam Định | B32: 2017 | C32: ='1_Du_lieu'!C37 -> ĐBSH | D32: =IF(B32<=2020,"2017–2020","2021–2024") -> 2017–2020 | E32: ='1_Du_lieu'!E37 -> 33.3 | F32: =AVERAGE('1_Du_lieu'!$E$5:$E$67) -> 31.157407 | G32: =E32/F32*100 -> 106.87667 | H32: ='1_Du_lieu'!F37/AVERAGE('1_Du_lieu'!$F$5:$F$67)*100 -> 103.61749 | I32: ='1_Du_lieu'!G37/AVERAGE('1_Du_lieu'!$G$5:$G$67)*100 -> 117.83681 | J32: ='1_Du_lieu'!H37/AVERAGE('1_Du_lieu'!$H$5:$H$67)*100 -> 80.892693 | K32: ='1_Du_lieu'!D37 -> 1
A33: Nghệ An | B33: 2017 | C33: ='1_Du_lieu'!C38 -> BTB&DHMT | D33: =IF(B33<=2020,"2017–2020","2021–2024") -> 2017–2020 | E33: ='1_Du_lieu'!E38 -> 30.7 | F33: =AVERAGE('1_Du_lieu'!$E$5:$E$67) -> 31.157407 | G33: =E33/F33*100 -> 98.531947 | H33: ='1_Du_lieu'!F38/AVERAGE('1_Du_lieu'!$F$5:$F$67)*100 -> 83.799937 | I33: ='1_Du_lieu'!G38/AVERAGE('1_Du_lieu'!$G$5:$G$67)*100 -> 88.560586 | J33: ='1_Du_lieu'!H38/AVERAGE('1_Du_lieu'!$H$5:$H$67)*100 -> 110.60838 | K33: ='1_Du_lieu'!D38 -> 0
A34: Ninh Bình | B34: 2017 | C34: ='1_Du_lieu'!C39 -> ĐBSH | D34: =IF(B34<=2020,"2017–2020","2021–2024") -> 2017–2020 | E34: ='1_Du_lieu'!E39 -> 29.6 | F34: =AVERAGE('1_Du_lieu'!$E$5:$E$67) -> 31.157407 | G34: =E34/F34*100 -> 95.001486 | H34: ='1_Du_lieu'!F39/AVERAGE('1_Du_lieu'!$F$5:$F$67)*100 -> 75.3067 | I34: ='1_Du_lieu'!G39/AVERAGE('1_Du_lieu'!$G$5:$G$67)*100 -> 98.319328 | J34: ='1_Du_lieu'!H39/AVERAGE('1_Du_lieu'!$H$5:$H$67)*100 -> 91.210639 | K34: ='1_Du_lieu'!D39 -> 1
A35: Ninh Thuận | B35: 2017 | C35: ='1_Du_lieu'!C40 -> BTB&DHMT | D35: =IF(B35<=2020,"2017–2020","2021–2024") -> 2017–2020 | E35: ='1_Du_lieu'!E40 -> 25.3 | F35: =AVERAGE('1_Du_lieu'!$E$5:$E$67) -> 31.157407 | G35: =E35/F35*100 -> 81.200594 | H35: ='1_Du_lieu'!F40/AVERAGE('1_Du_lieu'!$F$5:$F$67)*100 -> 61.151305 | I35: ='1_Du_lieu'!G40/AVERAGE('1_Du_lieu'!$G$5:$G$67)*100 -> 95.635674 | J35: ='1_Du_lieu'!H40/AVERAGE('1_Du_lieu'!$H$5:$H$67)*100 -> 78.003669 | K35: ='1_Du_lieu'!D40 -> 0
A36: Phú Thọ | B36: 2017 | C36: ='1_Du_lieu'!C41 -> TDMNPB | D36: =IF(B36<=2020,"2017–2020","2021–2024") -> 2017–2020 | E36: ='1_Du_lieu'!E41 -> 28.5 | F36: =AVERAGE('1_Du_lieu'!$E$5:$E$67) -> 31.157407 | G36: =E36/F36*100 -> 91.471025 | H36: ='1_Du_lieu'!F41/AVERAGE('1_Du_lieu'!$F$5:$F$67)*100 -> 74.740484 | I36: ='1_Du_lieu'!G41/AVERAGE('1_Du_lieu'!$G$5:$G$67)*100 -> 93.195988 | J36: ='1_Du_lieu'!H41/AVERAGE('1_Du_lieu'!$H$5:$H$67)*100 -> 97.814124 | K36: ='1_Du_lieu'!D41 -> 0
A37: Phú Yên | B37: 2017 | C37: ='1_Du_lieu'!C42 -> BTB&DHMT | D37: =IF(B37<=2020,"2017–2020","2021–2024") -> 2017–2020 | E37: ='1_Du_lieu'!E42 -> 25.4 | F37: =AVERAGE('1_Du_lieu'!$E$5:$E$67) -> 31.157407 | G37: =E37/F37*100 -> 81.521545 | H37: ='1_Du_lieu'!F42/AVERAGE('1_Du_lieu'!$F$5:$F$67)*100 -> 70.776974 | I37: ='1_Du_lieu'!G42/AVERAGE('1_Du_lieu'!$G$5:$G$67)*100 -> 90.268365 | J37: ='1_Du_lieu'!H42/AVERAGE('1_Du_lieu'!$H$5:$H$67)*100 -> 76.765515 | K37: ='1_Du_lieu'!D42 -> 0
A38: Quảng Bình | B38: 2017 | C38: ='1_Du_lieu'!C43 -> BTB&DHMT | D38: =IF(B38<=2020,"2017–2020","2021–2024") -> 2017–2020 | E38: ='1_Du_lieu'!E43 -> 25.3 | F38: =AVERAGE('1_Du_lieu'!$E$5:$E$67) -> 31.157407 | G38: =E38/F38*100 -> 81.200594 | H38: ='1_Du_lieu'!F43/AVERAGE('1_Du_lieu'!$F$5:$F$67)*100 -> 82.10129 | I38: ='1_Du_lieu'!G43/AVERAGE('1_Du_lieu'!$G$5:$G$67)*100 -> 79.28978 | J38: ='1_Du_lieu'!H43/AVERAGE('1_Du_lieu'!$H$5:$H$67)*100 -> 85.019872 | K38: ='1_Du_lieu'!D43 -> 0
A39: Quảng Nam | B39: 2017 | C39: ='1_Du_lieu'!C44 -> BTB&DHMT | D39: =IF(B39<=2020,"2017–2020","2021–2024") -> 2017–2020 | E39: ='1_Du_lieu'!E44 -> 29.2 | F39: =AVERAGE('1_Du_lieu'!$E$5:$E$67) -> 31.157407 | G39: =E39/F39*100 -> 93.717682 | H39: ='1_Du_lieu'!F44/AVERAGE('1_Du_lieu'!$F$5:$F$67)*100 -> 95.690469 | I39: ='1_Du_lieu'!G44/AVERAGE('1_Du_lieu'!$G$5:$G$67)*100 -> 89.53646 | J39: ='1_Du_lieu'!H44/AVERAGE('1_Du_lieu'!$H$5:$H$67)*100 -> 96.988688 | K39: ='1_Du_lieu'!D44 -> 0
... A42: Quảng Trị | B42: 2017 | C42: ='1_Du_lieu'!C47 -> BTB&DHMT | D42: =IF(B42<=2020,"2017–2020","2021–2024") -> 2017–2020 | E42: ='1_Du_lieu'!E47 -> 25.7 | F42: =AVERAGE('1_Du_lieu'!$E$5:$E$67) -> 31.157407 | G42: =E42/F42*100 -> 82.484398 | H42: ='1_Du_lieu'!F47/AVERAGE('1_Du_lieu'!$F$5:$F$67)*100 -> 77.571563 | I42: ='1_Du_lieu'!G47/AVERAGE('1_Du_lieu'!$G$5:$G$67)*100 -> 75.874221 | J42: ='1_Du_lieu'!H47/AVERAGE('1_Du_lieu'!$H$5:$H$67)*100 -> 103.59217 | K42: ='1_Du_lieu'!D47 -> 0
A43: TP. Hồ Chí Minh | B43: 2017 | C43: ='1_Du_lieu'!C50 -> ĐNB | D43: =IF(B43<=2020,"2017–2020","2021–2024") -> 2017–2020 | E43: ='1_Du_lieu'!E50 -> 78.6 | F43: =AVERAGE('1_Du_lieu'!$E$5:$E$67) -> 31.157407 | G43: =E43/F43*100 -> 252.26746 | H43: ='1_Du_lieu'!F50/AVERAGE('1_Du_lieu'!$F$5:$F$67)*100 -> 484.1145 | I43: ='1_Du_lieu'!G50/AVERAGE('1_Du_lieu'!$G$5:$G$67)*100 -> 176.63323 | J43: ='1_Du_lieu'!H50/AVERAGE('1_Du_lieu'!$H$5:$H$67)*100 -> 317.79272 | K43: ='1_Du_lieu'!D50 -> 1
...

Sheet 4_Bang3_Gini_Theil
A1: BẢNG 3. Gini, CV, Theil-T, MLD và phân rã theo 6 vùng – tính riêng từng năm trên các tỉnh có EBI
A2: Mỗi dòng = một tỉnh–năm (445 dòng, sắp theo năm). Cột "j" = thứ hạng trong năm (RANK.AVG, tăng dần). Gini = 2Σ(j·y)/(N·Σy) − (N+1)/N. Theil-T = Σ(y/ȳ)ln(y/ȳ)/N; MLD = Σln(ȳ/y)/N. Cột "f" = 1 nếu là Hà Nội hoặc TP.HCM (dùng cho kiểm tra vững).
A4: Tỉnh | B4: Năm | C4: Vùng | D4: y = EBI | E4: f (HN/HCM) | F4: ȳ năm | G4: N năm | H4: j = hạng | I4: j·y | J4: y/ȳ | K4: ln(y/ȳ) | L4: (y/ȳ)ln(y/ȳ) | M4: ln(ȳ/y) [MLD] | N4: ln(y) | O4: ȳ_ex (bỏ HN,HCM) | P4: (1−f)(y/ȳ_ex)ln(y/ȳ_ex)
A5: An Giang | B5: 2017 | C5: ='1_Du_lieu'!C5 -> ĐBSCL | D5: ='1_Du_lieu'!E5 -> 27.2 | E5: =IF(OR(A5="Hà Nội",A5="TP. Hồ Chí Minh"),1,0) -> 0 | F5: =AVERAGE($D$5:$D$58) -> 31.157407 | G5: =COUNT($D$5:$D$58) -> 54 | H5: =_xlfn.RANK.AVG(D5,$D$5:$D$58,1) -> 22.5 | I5: =H5*D5 -> 612 | J5: =D5/F5 -> 0.87298663 | K5: =LN(J5) -> -0.13583504 | L5: =J5*K5 -> -0.11858217 | M5: =LN(F5/D5) -> 0.13583504 | N5: =LN(D5) -> 3.303217 | O5: =SUMPRODUCT((1-$E$5:$E$58)*$D$5:$D$58)/(G5-SUM($E$5:$E$58)) -> 29.386538 | P5: =(1-E5)*(D5/O5)*LN(D5/O5) -> -0.07156666
A6: Bà Rịa - Vũng Tàu | B6: 2017 | C6: ='1_Du_lieu'!C6 -> ĐNB | D6: ='1_Du_lieu'!E6 -> 37.8 | E6: =IF(OR(A6="Hà Nội",A6="TP. Hồ Chí Minh"),1,0) -> 0 | F6: =AVERAGE($D$5:$D$58) -> 31.157407 | G6: =COUNT($D$5:$D$58) -> 54 | H6: =_xlfn.RANK.AVG(D6,$D$5:$D$58,1) -> 48 | I6: =H6*D6 -> 1814.4 | J6: =D6/F6 -> 1.2131947 | K6: =LN(J6) -> 0.19325709 | L6: =J6*K6 -> 0.23445846 | M6: =LN(F6/D6) -> -0.19325709 | N6: =LN(D6) -> 3.6323091 | O6: =SUMPRODUCT((1-$E$5:$E$58)*$D$5:$D$58)/(G6-SUM($E$5:$E$58)) -> 29.386538 | P6: =(1-E6)*(D6/O6)*LN(D6/O6) -> 0.32385567
A7: Bình Dương | B7: 2017 | C7: ='1_Du_lieu'!C7 -> ĐNB | D7: ='1_Du_lieu'!E7 -> 43 | E7: =IF(OR(A7="Hà Nội",A7="TP. Hồ Chí Minh"),1,0) -> 0 | F7: =AVERAGE($D$5:$D$58) -> 31.157407 | G7: =COUNT($D$5:$D$58) -> 54 | H7: =_xlfn.RANK.AVG(D7,$D$5:$D$58,1) -> 51 | I7: =H7*D7 -> 2193 | J7: =D7/F7 -> 1.3800892 | K7: =LN(J7) -> 0.3221481 | L7: =J7*K7 -> 0.4445931 | M7: =LN(F7/D7) -> -0.3221481 | N7: =LN(D7) -> 3.7612001 | O7: =SUMPRODUCT((1-$E$5:$E$58)*$D$5:$D$58)/(G7-SUM($E$5:$E$58)) -> 29.386538 | P7: =(1-E7)*(D7/O7)*LN(D7/O7) -> 0.55700766
A8: Bình Phước | B8: 2017 | C8: ='1_Du_lieu'!C8 -> ĐNB | D8: ='1_Du_lieu'!E8 -> 24 | E8: =IF(OR(A8="Hà Nội",A8="TP. Hồ Chí Minh"),1,0) -> 0 | F8: =AVERAGE($D$5:$D$58) -> 31.157407 | G8: =COUNT($D$5:$D$58) -> 54 | H8: =_xlfn.RANK.AVG(D8,$D$5:$D$58,1) -> 7 | I8: =H8*D8 -> 168 | J8: =D8/F8 -> 0.77028232 | K8: =LN(J8) -> -0.26099818 | L8: =J8*K8 -> -0.20104229 | M8: =LN(F8/D8) -> 0.26099818 | N8: =LN(D8) -> 3.1780538 | O8: =SUMPRODUCT((1-$E$5:$E$58)*$D$5:$D$58)/(G8-SUM($E$5:$E$58)) -> 29.386538 | P8: =(1-E8)*(D8/O8)*LN(D8/O8) -> -0.16536785
A9: Bình Thuận | B9: 2017 | C9: ='1_Du_lieu'!C9 -> BTB&DHMT | D9: ='1_Du_lieu'!E9 -> 29.5 | E9: =IF(OR(A9="Hà Nội",A9="TP. Hồ Chí Minh"),1,0) -> 0 | F9: =AVERAGE($D$5:$D$58) -> 31.157407 | G9: =COUNT($D$5:$D$58) -> 54 | H9: =_xlfn.RANK.AVG(D9,$D$5:$D$58,1) -> 33.5 | I9: =H9*D9 -> 988.25 | J9: =D9/F9 -> 0.94680535 | K9: =LN(J9) -> -0.054661752 | L9: =J9*K9 -> -0.051754039 | M9: =LN(F9/D9) -> 0.054661752 | N9: =LN(D9) -> 3.3843903 | O9: =SUMPRODUCT((1-$E$5:$E$58)*$D$5:$D$58)/(G9-SUM($E$5:$E$58)) -> 29.386538 | P9: =(1-E9)*(D9/O9)*LN(D9/O9) -> 0.003868448
A10: Bình Định | B10: 2017 | C10: ='1_Du_lieu'!C10 -> BTB&DHMT | D10: ='1_Du_lieu'!E10 -> 29.9 | E10: =IF(OR(A10="Hà Nội",A10="TP. Hồ Chí Minh"),1,0) -> 0 | F10: =AVERAGE($D$5:$D$58) -> 31.157407 | G10: =COUNT($D$5:$D$58) -> 54 | H10: =_xlfn.RANK.AVG(D10,$D$5:$D$58,1) -> 36 | I10: =H10*D10 -> 1076.4 | J10: =D10/F10 -> 0.95964339 | K10: =LN(J10) -> -0.041193535 | L10: =J10*K10 -> -0.039531103 | M10: =LN(F10/D10) -> 0.041193535 | N10: =LN(D10) -> 3.3978585 | O10: =SUMPRODUCT((1-$E$5:$E$58)*$D$5:$D$58)/(G10-SUM($E$5:$E$58)) -> 29.386538 | P10: =(1-E10)*(D10/O10)*LN(D10/O10) -> 0.017624444
A11: Bắc Giang | B11: 2017 | C11: ='1_Du_lieu'!C12 -> TDMNPB | D11: ='1_Du_lieu'!E12 -> 30 | E11: =IF(OR(A11="Hà Nội",A11="TP. Hồ Chí Minh"),1,0) -> 0 | F11: =AVERAGE($D$5:$D$58) -> 31.157407 | G11: =COUNT($D$5:$D$58) -> 54 | H11: =_xlfn.RANK.AVG(D11,$D$5:$D$58,1) -> 37 | I11: =H11*D11 -> 1110 | J11: =D11/F11 -> 0.9628529 | K11: =LN(J11) -> -0.037854633 | L11: =J11*K11 -> -0.036448443 | M11: =LN(F11/D11) -> 0.037854633 | N11: =LN(D11) -> 3.4011974 | O11: =SUMPRODUCT((1-$E$5:$E$58)*$D$5:$D$58)/(G11-SUM($E$5:$E$58)) -> 29.386538 | P11: =(1-E11)*(D11/O11)*LN(D11/O11) -> 0.021091992
A12: Bắc Kạn | B12: 2017 | C12: ='1_Du_lieu'!C13 -> TDMNPB | D12: ='1_Du_lieu'!E13 -> 22.6 | E12: =IF(OR(A12="Hà Nội",A12="TP. Hồ Chí Minh"),1,0) -> 0 | F12: =AVERAGE($D$5:$D$58) -> 31.157407 | G12: =COUNT($D$5:$D$58) -> 54 | H12: =_xlfn.RANK.AVG(D12,$D$5:$D$58,1) -> 3 | I12: =H12*D12 -> 67.8 | J12: =D12/F12 -> 0.72534918 | K12: =LN(J12) -> -0.32110211 | L12: =J12*K12 -> -0.23291115 | M12: =LN(F12/D12) -> 0.32110211 | N12: =LN(D12) -> 3.1179499 | O12: =SUMPRODUCT((1-$E$5:$E$58)*$D$5:$D$58)/(G12-SUM($E$5:$E$58)) -> 29.386538 | P12: =(1-E12)*(D12/O12)*LN(D12/O12) -> -0.20194489
A13: Bắc Ninh | B13: 2017 | C13: ='1_Du_lieu'!C14 -> ĐBSH | D13: ='1_Du_lieu'!E14 -> 38.9 | E13: =IF(OR(A13="Hà Nội",A13="TP. Hồ Chí Minh"),1,0) -> 0 | F13: =AVERAGE($D$5:$D$58) -> 31.157407 | G13: =COUNT($D$5:$D$58) -> 54 | H13: =_xlfn.RANK.AVG(D13,$D$5:$D$58,1) -> 49 | I13: =H13*D13 -> 1906.1 | J13: =D13/F13 -> 1.2484993 | K13: =LN(J13) -> 0.22194224 | L13: =J13*K13 -> 0.27709472 | M13: =LN(F13/D13) -> -0.22194224 | N13: =LN(D13) -> 3.6609943 | O13: =SUMPRODUCT((1-$E$5:$E$58)*$D$5:$D$58)/(G13-SUM($E$5:$E$58)) -> 29.386538 | P13: =(1-E13)*(D13/O13)*LN(D13/O13) -> 0.37125158
A14: Bến Tre | B14: 2017 | C14: ='1_Du_lieu'!C15 -> ĐBSCL | D14: ='1_Du_lieu'!E15 -> 28.1 | E14: =IF(OR(A14="Hà Nội",A14="TP. Hồ Chí Minh"),1,0) -> 0 | F14: =AVERAGE($D$5:$D$58) -> 31.157407 | G14: =COUNT($D$5:$D$58) -> 54 | H14: =_xlfn.RANK.AVG(D14,$D$5:$D$58,1) -> 27.5 | I14: =H14*D14 -> 772.75 | J14: =D14/F14 -> 0.90187221 | K14: =LN(J14) -> -0.10328244 | L14: =J14*K14 -> -0.093147562 | M14: =LN(F14/D14) -> 0.10328244 | N14: =LN(D14) -> 3.3357696 | O14: =SUMPRODUCT((1-$E$5:$E$58)*$D$5:$D$58)/(G14-SUM($E$5:$E$58)) -> 29.386538 | P14: =(1-E14)*(D14/O14)*LN(D14/O14) -> -0.04280722
A15: Cà Mau | B15: 2017 | C15: ='1_Du_lieu'!C17 -> ĐBSCL | D15: ='1_Du_lieu'!E17 -> 21.2 | E15: =IF(OR(A15="Hà Nội",A15="TP. Hồ Chí Minh"),1,0) -> 0 | F15: =AVERAGE($D$5:$D$58) -> 31.157407 | G15: =COUNT($D$5:$D$58) -> 54 | H15: =_xlfn.RANK.AVG(D15,$D$5:$D$58,1) -> 1.5 | I15: =H15*D15 -> 31.8 | J15: =D15/F15 -> 0.68041605 | K15: =LN(J15) -> -0.38505083 | L15: =J15*K15 -> -0.26199477 | M15: =LN(F15/D15) -> 0.38505083 | N15: =LN(D15) -> 3.0540012 | O15: =SUMPRODUCT((1-$E$5:$E$58)*$D$5:$D$58)/(G15-SUM($E$5:$E$58)) -> 29.386538 | P15: =(1-E15)*(D15/O15)*LN(D15/O15) -> -0.23556884
A16: Cần Thơ | B16: 2017 | C16: ='1_Du_lieu'!C18 -> ĐBSCL | D16: ='1_Du_lieu'!E18 -> 37.2 | E16: =IF(OR(A16="Hà Nội",A16="TP. Hồ Chí Minh"),1,0) -> 0 | F16: =AVERAGE($D$5:$D$58) -> 31.157407 | G16: =COUNT($D$5:$D$58) -> 54 | H16: =_xlfn.RANK.AVG(D16,$D$5:$D$58,1) -> 47 | I16: =H16*D16 -> 1748.4 | J16: =D16/F16 -> 1.1939376 | K16: =LN(J16) -> 0.17725675 | L16: =J16*K16 -> 0.21163349 | M16: =LN(F16/D16) -> -0.17725675 | N16: =LN(D16) -> 3.6163088 | O16: =SUMPRODUCT((1-$E$5:$E$58)*$D$5:$D$58)/(G16-SUM($E$5:$E$58)) -> 29.386538 | P16: =(1-E16)*(D16/O16)*LN(D16/O16) -> 0.2984605
A17: Gia Lai | B17: 2017 | C17: ='1_Du_lieu'!C19 -> TN | D17: ='1_Du_lieu'!E19 -> 23.7 | E17: =IF(OR(A17="Hà Nội",A17="TP. Hồ Chí Minh"),1,0) -> 0 | F17: =AVERAGE($D$5:$D$58) -> 31.157407 | G17: =COUNT($D$5:$D$58) -> 54 | H17: =_xlfn.RANK.AVG(D17,$D$5:$D$58,1) -> 5.5 | I17: =H17*D17 -> 130.35 | J17: =D17/F17 -> 0.76065379 | K17: =LN(J17) -> -0.27357697 | L17: =J17*K17 -> -0.20809736 | M17: =LN(F17/D17) -> 0.27357697 | N17: =LN(D17) -> 3.165475 | O17: =SUMPRODUCT((1-$E$5:$E$58)*$D$5:$D$58)/(G17-SUM($E$5:$E$58)) -> 29.386538 | P17: =(1-E17)*(D17/O17)*LN(D17/O17) -> -0.17344544
